<?xml version="1.0" ?><robot name="sysID_2XC430">  
  <link name="2xc430">    
    <visual>      
      <origin xyz="0 0 0" rpy="0 -0 0"/>      
      <geometry>        
        <mesh filename="package:///meshes/2xc430_visual.stl"/>        
      </geometry>      
      <material name="2xc430_material">        
        <color rgba="0.53778433395328428812 0.5264357970166424483 0.5155377112718237953 1.0"/>        
      </material>      
    </visual>    
    <collision>      
      <origin xyz="0 0 0" rpy="0 -0 0"/>      
      <geometry>        
        <mesh filename="package:///meshes/2xc430_collision.stl"/>        
      </geometry>      
    </collision>    
    <inertial>      
      <origin xyz="0.075524953696132282599 0.017886243519076083786 0.0056748822304184586354" rpy="0 0 0"/>      
      <mass value="0.13164999999836235478"/>      
      <inertia ixx="4.5973499788565170057e-05" ixy="-6.3707692171101867995e-06" ixz="-6.4106848464462649908e-07" iyy="4.4966269289965505717e-05" iyz="-1.4151876066262353929e-07" izz="5.8942005476165127299e-05"/>      
    </inertial>    
  </link>  

  <link name="arm_430">    
    <visual>      
      <origin xyz="0 0 0" rpy="0 -0 0"/>      
      <geometry>        
        <mesh filename="package:///meshes/arm_430_visual.stl"/>        
      </geometry>      
      <material name="arm_430_material">        
        <color rgba="0.63059283987567615881 0.65298952457695413898 0.67418901807298259321 1.0"/>        
      </material>      
    </visual>    
    <collision>      
      <origin xyz="0 0 0" rpy="0 -0 0"/>      
      <geometry>        
        <mesh filename="package:///meshes/arm_430_collision.stl"/>        
      </geometry>      
    </collision>    
    <inertial>      
      <origin xyz="-0.077790387031996671707 -1.3637865612687968304e-05 -0.019000000000000103612" rpy="0 0 0"/>      
      <mass value="0.25549999999999989386"/>      
      <inertia ixx="0.00024426144376379248842" ixy="9.4015858830725975485e-08" ixz="-8.271998648043313894e-19" iyy="0.00041073874164068095282" iyz="1.466732916362913053e-16" izz="0.00022084196523238861366"/>      
    </inertial>    
  </link>  

  <joint name="joint_0" type="revolute">    
    <origin xyz="0.096000000152447806379 0.032699858643998935825 0.0062193960984139899303" rpy="-1.5707963267948961139 1.0547118733939117296e-15 -1.5707963267948950037"/>    
    <parent link="2xc430"/>    
    <child link="arm_430"/>    
    <axis xyz="0 0 1"/>    
    <limit effort="1" velocity="20" lower="-1.570796326794896558" upper="1.570796326794896558"/>    
    <joint_properties friction="0.0"/>    
  </joint>  


</robot>