<?xml version="1.0" ?><robot name="left_arm_umi">  
  <link name="sho_pitch_link">    
    <visual>      
      <origin xyz="0 0 0" rpy="0 -0 0"/>      
      <geometry>        
        <mesh filename="package:///meshes/left_sho_pitch_link_visual.stl"/>        
      </geometry>      
      <material name="sho_pitch_link_material">        
        <color rgba="0.61568627450980395466 0.81176470588235294379 0.92941176470588227065 1.0"/>        
      </material>      
    </visual>    
    <collision>      
      <origin xyz="0 0 0" rpy="0 -0 0"/>      
      <geometry>        
        <mesh filename="package:///meshes/left_sho_pitch_link_collision.stl"/>        
      </geometry>      
    </collision>    
    <inertial>      
      <origin xyz="-1.025903438159899119e-18 -2.1966078074444220184e-18 0.012913250798677602602" rpy="0 0 0"/>      
      <mass value="0.0085999999999999982708"/>      
      <inertia ixx="1.8365636406635814379e-06" ixy="0" ixz="0" iyy="4.0110869076839152165e-06" iyz="0" izz="3.5160516450492493809e-06"/>      
    </inertial>    
  </link>  

  <link name="2xl430_gears">    
    <visual>      
      <origin xyz="0 0 0" rpy="0 -0 0"/>      
      <geometry>        
        <mesh filename="package:///meshes/left_2xl430_gears_visual.stl"/>        
      </geometry>      
      <material name="2xl430_gears_material">        
        <color rgba="0.75914767920569214965 0.85560384745670925444 0.90519468321360607721 1.0"/>        
      </material>      
    </visual>    
    <collision>      
      <origin xyz="0 0 0" rpy="0 -0 0"/>      
      <geometry>        
        <mesh filename="package:///meshes/left_2xl430_gears_collision.stl"/>        
      </geometry>      
    </collision>    
    <inertial>      
      <origin xyz="-0.011592905737980642444 -0.0024238553642583816373 -0.018551095523802015735" rpy="0 0 0"/>      
      <mass value="0.11800003674524911501"/>      
      <inertia ixx="2.7511021050428206944e-05" ixy="9.0043904315036704004e-07" ixz="-2.3349710124172453411e-08" iyy="3.2796197843345624423e-05" iyz="-6.5715119654599577247e-07" izz="3.5775739835744996948e-05"/>      
    </inertial>    
  </link>  

  <link name="spur_1m_24t_drive">    
    <visual>      
      <origin xyz="0 0 0" rpy="0 -0 0"/>      
      <geometry>        
        <mesh filename="package:///meshes/left_spur_1m_24t_drive_visual.stl"/>        
      </geometry>      
      <material name="spur_1m_24t_drive_material">        
        <color rgba="0.61568627450980395466 0.81176470588235294379 0.92941176470588238168 1.0"/>        
      </material>      
    </visual>    
    <collision>      
      <origin xyz="0 0 0" rpy="0 -0 0"/>      
      <geometry>        
        <mesh filename="package:///meshes/left_spur_1m_24t_drive_collision.stl"/>        
      </geometry>      
    </collision>    
    <inertial>      
      <origin xyz="3.0395421551447426547e-15 -3.3912620813973872492e-16 0.0048096451474093065287" rpy="0 0 0"/>      
      <mass value="0.0031999999999999997197"/>      
      <inertia ixx="1.4097598887016953379e-07" ixy="1.5562823114943523235e-15" ixz="7.4273784759770902112e-37" iyy="1.4097598803635996198e-07" iyz="7.8038995636436382948e-37" izz="2.4107776386988835496e-07"/>      
    </inertial>    
  </link>  

  <joint name="left_sho_yaw_drive" type="revolute">    
    <origin xyz="-0.024000000716142534662 -0.019000000152456227726 -0.019000000152442717699" rpy="1.5707963267945506125 -5.5729871745090160275e-14 6.2805146429461445464e-14"/>    
    <parent link="2xl430_gears"/>    
    <child link="spur_1m_24t_drive"/>    
    <axis xyz="0 0 1"/>    
    <limit effort="1" velocity="20" lower="-2.6179938779914944114" upper="2.6179938779914944114"/>    
    <joint_properties friction="0.0"/>    
  </joint>  

  <link name="spur_1m_24t_driven">    
    <visual>      
      <origin xyz="0 0 0" rpy="0 -0 0"/>      
      <geometry>        
        <mesh filename="package:///meshes/left_spur_1m_24t_driven_visual.stl"/>        
      </geometry>      
      <material name="spur_1m_24t_driven_material">        
        <color rgba="0.23137254901960788156 0.38039215686274502337 0.7058823529411765163 1.0"/>        
      </material>      
    </visual>    
    <collision>      
      <origin xyz="0 0 0" rpy="0 -0 0"/>      
      <geometry>        
        <mesh filename="package:///meshes/left_spur_1m_24t_driven_collision.stl"/>        
      </geometry>      
    </collision>    
    <inertial>      
      <origin xyz="-2.6903043908340867984e-18 -1.688384205958136519e-15 -0.00097237500038395777158" rpy="0 0 0"/>      
      <mass value="0.0026999999999999997093"/>      
      <inertia ixx="1.2202334915684080498e-07" ixy="1.3837295890494949211e-37" ixz="-1.0447421496749939075e-36" iyy="1.2202334915684064616e-07" iyz="3.3220397498769138301e-37" izz="2.3180293204341252239e-07"/>      
    </inertial>    
  </link>  

  <link name="sho_yaw_link">    
    <visual>      
      <origin xyz="0 0 0" rpy="0 -0 0"/>      
      <geometry>        
        <mesh filename="package:///meshes/left_sho_yaw_link_visual.stl"/>        
      </geometry>      
      <material name="sho_yaw_link_material">        
        <color rgba="0.61568627450980395466 0.81176470588235294379 0.92941176470588238168 1.0"/>        
      </material>      
    </visual>    
    <collision>      
      <origin xyz="0 0 0" rpy="0 -0 0"/>      
      <geometry>        
        <mesh filename="package:///meshes/left_sho_yaw_link_collision.stl"/>        
      </geometry>      
    </collision>    
    <inertial>      
      <origin xyz="-4.7730210054629770351e-18 2.6069328434163573568e-18 -0.024649285094360089132" rpy="0 0 0"/>      
      <mass value="0.014500000000000007674"/>      
      <inertia ixx="9.2365904614004439553e-06" ixy="3.5862833440690451918e-13" ixz="-8.2397007242855601464e-43" iyy="5.8163826335078791714e-06" iyz="-5.4352775587714288989e-35" izz="4.5074356741562122031e-06"/>      
    </inertial>    
  </link>  

  <link name="2xl430_gears_2">    
    <visual>      
      <origin xyz="0 0 0" rpy="0 -0 0"/>      
      <geometry>        
        <mesh filename="package:///meshes/left_2xl430_gears_2_visual.stl"/>        
      </geometry>      
      <material name="2xl430_gears_2_material">        
        <color rgba="0.75914767920569214965 0.85560384745670925444 0.90519468321360607721 1.0"/>        
      </material>      
    </visual>    
    <collision>      
      <origin xyz="0 0 0" rpy="0 -0 0"/>      
      <geometry>        
        <mesh filename="package:///meshes/left_2xl430_gears_2_collision.stl"/>        
      </geometry>      
    </collision>    
    <inertial>      
      <origin xyz="-0.011592905737981091738 -0.0024238553642542742458 -0.018551095523813909" rpy="0 0 0"/>      
      <mass value="0.11800003674524911501"/>      
      <inertia ixx="2.751102105042832214e-05" ixy="9.0043904315329650349e-07" ixz="-2.3349710125436329138e-08" iyy="3.2796197843348145193e-05" iyz="-6.5715119655126410565e-07" izz="3.5775739835745051158e-05"/>      
    </inertial>    
  </link>  

  <link name="spur_1m_24t_drive_2">    
    <visual>      
      <origin xyz="0 0 0" rpy="0 -0 0"/>      
      <geometry>        
        <mesh filename="package:///meshes/left_spur_1m_24t_drive_2_visual.stl"/>        
      </geometry>      
      <material name="spur_1m_24t_drive_2_material">        
        <color rgba="0.61568627450980395466 0.81176470588235294379 0.92941176470588238168 1.0"/>        
      </material>      
    </visual>    
    <collision>      
      <origin xyz="0 0 0" rpy="0 -0 0"/>      
      <geometry>        
        <mesh filename="package:///meshes/left_spur_1m_24t_drive_2_collision.stl"/>        
      </geometry>      
    </collision>    
    <inertial>      
      <origin xyz="3.0395421551447426547e-15 -3.3912620811388947869e-16 0.0048096451474092995898" rpy="0 0 0"/>      
      <mass value="0.0031999999999999997197"/>      
      <inertia ixx="1.4097598887016953379e-07" ixy="1.5562823102285579479e-15" ixz="2.9661020669666376683e-36" iyy="1.4097598803635998845e-07" iyz="9.1368612700525381613e-36" izz="2.4107776386988835496e-07"/>      
    </inertial>    
  </link>  

  <joint name="left_elbow_yaw_drive" type="revolute">    
    <origin xyz="-0.024000000716140806878 -0.019000000152450138846 -0.01900000015246447807" rpy="1.5707963267949478503 -2.5802640142449200815e-13 5.2180482157376444099e-14"/>    
    <parent link="2xl430_gears_2"/>    
    <child link="spur_1m_24t_drive_2"/>    
    <axis xyz="0 0 1"/>    
    <limit effort="1" velocity="20" lower="-2.6179938779914944114" upper="2.6179938779914944114"/>    
    <joint_properties friction="0.0"/>    
  </joint>  

  <link name="spur_1m_24t_driven_2">    
    <visual>      
      <origin xyz="0 0 0" rpy="0 -0 0"/>      
      <geometry>        
        <mesh filename="package:///meshes/left_spur_1m_24t_driven_2_visual.stl"/>        
      </geometry>      
      <material name="spur_1m_24t_driven_2_material">        
        <color rgba="0.23137254901960788156 0.38039215686274502337 0.7058823529411765163 1.0"/>        
      </material>      
    </visual>    
    <collision>      
      <origin xyz="0 0 0" rpy="0 -0 0"/>      
      <geometry>        
        <mesh filename="package:///meshes/left_spur_1m_24t_driven_2_collision.stl"/>        
      </geometry>      
    </collision>    
    <inertial>      
      <origin xyz="-2.6903043908350131707e-18 -1.685153565132015999e-15 -0.00097237500038395083268" rpy="0 0 0"/>      
      <mass value="0.0026999999999999997093"/>      
      <inertia ixx="1.2202334915684080498e-07" ixy="-5.3426136268858280334e-65" ixz="-2.7609150325300431337e-36" iyy="1.2202334915684064616e-07" iyz="5.8515286657488347587e-36" izz="2.3180293204341252239e-07"/>      
    </inertial>    
  </link>  

  <link name="elb_yaw_link">    
    <visual>      
      <origin xyz="0 0 0" rpy="0 -0 0"/>      
      <geometry>        
        <mesh filename="package:///meshes/left_elb_yaw_link_visual.stl"/>        
      </geometry>      
      <material name="elb_yaw_link_material">        
        <color rgba="0.61568627450980395466 0.81176470588235294379 0.92941176470588227065 1.0"/>        
      </material>      
    </visual>    
    <collision>      
      <origin xyz="0 0 0" rpy="0 -0 0"/>      
      <geometry>        
        <mesh filename="package:///meshes/left_elb_yaw_link_collision.stl"/>        
      </geometry>      
    </collision>    
    <inertial>      
      <origin xyz="5.3127688027774929136e-08 0.0019833638641961618201 -0.023416643551549959357" rpy="0 0 0"/>      
      <mass value="0.017500000000000005135"/>      
      <inertia ixx="1.4134344903109199776e-05" ixy="1.6945783922006120707e-12" ixz="-1.1286398721833143996e-11" iyy="6.6435900776211374285e-06" iyz="1.0545227077253055462e-06" izz="8.9925290757999027595e-06"/>      
    </inertial>    
  </link>  

  <link name="spur_1m_24t_driven_3">    
    <visual>      
      <origin xyz="0 0 0" rpy="0 -0 0"/>      
      <geometry>        
        <mesh filename="package:///meshes/left_spur_1m_24t_driven_3_visual.stl"/>        
      </geometry>      
      <material name="spur_1m_24t_driven_3_material">        
        <color rgba="0.23137254901960788156 0.38039215686274502337 0.7058823529411765163 1.0"/>        
      </material>      
    </visual>    
    <collision>      
      <origin xyz="0 0 0" rpy="0 -0 0"/>      
      <geometry>        
        <mesh filename="package:///meshes/left_spur_1m_24t_driven_3_collision.stl"/>        
      </geometry>      
    </collision>    
    <inertial>      
      <origin xyz="-2.6903043908334539378e-18 -1.6883842059581396744e-15 -0.0025723750003839550293" rpy="0 0 0"/>      
      <mass value="0.0026999999999999997093"/>      
      <inertia ixx="1.2202334915684080498e-07" ixy="1.650838217124924475e-37" ixz="5.8515286657488347587e-36" iyy="1.2202334915684064616e-07" iyz="0" izz="2.3180293204341252239e-07"/>      
    </inertial>    
  </link>  

  <link name="2xl430_gears_3">    
    <visual>      
      <origin xyz="0 0 0" rpy="0 -0 0"/>      
      <geometry>        
        <mesh filename="package:///meshes/left_2xl430_gears_3_visual.stl"/>        
      </geometry>      
      <material name="2xl430_gears_3_material">        
        <color rgba="0.75914767920569214965 0.85560384745670925444 0.90519468321360607721 1.0"/>        
      </material>      
    </visual>    
    <collision>      
      <origin xyz="0 0 0" rpy="0 -0 0"/>      
      <geometry>        
        <mesh filename="package:///meshes/left_2xl430_gears_3_collision.stl"/>        
      </geometry>      
    </collision>    
    <inertial>      
      <origin xyz="0.00044890447619909743101 0.011592905379898219356 -0.024576144788197168412" rpy="0 0 0"/>      
      <mass value="0.11800003674524911501"/>      
      <inertia ixx="3.5775739835742089931e-05" ixy="2.3349710123834755271e-08" ixz="6.5715119654965728415e-07" iyy="2.7511021050427807144e-05" iyz="9.0043904315220340747e-07" izz="3.2796197843345726067e-05"/>      
    </inertial>    
  </link>  

  <link name="spur_1m_24t_drive_3">    
    <visual>      
      <origin xyz="0 0 0" rpy="0 -0 0"/>      
      <geometry>        
        <mesh filename="package:///meshes/left_spur_1m_24t_drive_3_visual.stl"/>        
      </geometry>      
      <material name="spur_1m_24t_drive_3_material">        
        <color rgba="0.61568627450980395466 0.81176470588235294379 0.92941176470588238168 1.0"/>        
      </material>      
    </visual>    
    <collision>      
      <origin xyz="0 0 0" rpy="0 -0 0"/>      
      <geometry>        
        <mesh filename="package:///meshes/left_spur_1m_24t_drive_3_collision.stl"/>        
      </geometry>      
    </collision>    
    <inertial>      
      <origin xyz="3.0326032612408350319e-15 -3.3912620811388928147e-16 0.0048096451474093030592" rpy="0 0 0"/>      
      <mass value="0.0031999999999999997197"/>      
      <inertia ixx="1.4097598887016953379e-07" ixy="1.5562823135372803981e-15" ixz="1.2722418906858421266e-35" iyy="1.4097598803635998845e-07" iyz="4.1397718535750480265e-37" izz="2.4107776386988835496e-07"/>      
    </inertial>    
  </link>  

  <joint name="left_wrist_pitch_drive" type="revolute">    
    <origin xyz="-1.5244492967147879128e-10 0.024000000358059658812 -0.0080000000000056449567" rpy="-3.0533404903795228175e-14 -1.7699329119283895979e-13 -1.5707963267949680564"/>    
    <parent link="2xl430_gears_3"/>    
    <child link="spur_1m_24t_drive_3"/>    
    <axis xyz="0 0 1"/>    
    <limit effort="1" velocity="20" lower="-1.9198621771937625091" upper="1.3962634015954635824"/>    
    <joint_properties friction="0.0"/>    
  </joint>  

  <link name="hand">    
    <visual>      
      <origin xyz="0 0 0" rpy="0 -0 0"/>      
      <geometry>        
        <mesh filename="package:///meshes/left_hand_visual.stl"/>        
      </geometry>      
      <material name="hand_material">        
        <color rgba="0.6414991312980887761 0.67624720774385704836 0.69709605361131787848 1.0"/>        
      </material>      
    </visual>    
    <collision>      
      <origin xyz="0 0 0" rpy="0 -0 0"/>      
      <geometry>        
        <mesh filename="package:///meshes/left_hand_collision.stl"/>        
      </geometry>      
    </collision>    
    <inertial>      
      <origin xyz="0.0037132560743682414481 -0.042135580180293757957 -0.019513129422372377242" rpy="0 0 0"/>      
      <mass value="0.039500000000000000389"/>      
      <inertia ixx="2.4655505305535776886e-05" ixy="6.2292690516533964304e-07" ixz="1.3905202790272152079e-08" iyy="2.5499495709674505013e-05" iyz="-4.0482284361498457642e-08" izz="1.3476712281039049114e-05"/>      
    </inertial>    
  </link>  

  <joint name="left_wrist_roll" type="revolute">    
    <origin xyz="0.019000000000009276829 -3.5808436771311846769e-10 -0.027000000152447547336" rpy="1.2196020852255911422e-29 1.5707963267946087882 0"/>    
    <parent link="2xl430_gears_3"/>    
    <child link="hand"/>    
    <axis xyz="0 0 1"/>    
    <limit effort="1" velocity="20" lower="-1.9198621771937625091" upper="1.3962634015954635824"/>    
    <joint_properties friction="0.0"/>    
  </joint>  

  <link name="wrist_bearing_plate">    
    <visual>      
      <origin xyz="0 0 0" rpy="0 -0 0"/>      
      <geometry>        
        <mesh filename="package:///meshes/left_wrist_bearing_plate_visual.stl"/>        
      </geometry>      
      <material name="wrist_bearing_plate_material">        
        <color rgba="0.71932243125689054875 0.63128434304969727187 0.52422389360984933404 1.0"/>        
      </material>      
    </visual>    
    <collision>      
      <origin xyz="0 0 0" rpy="0 -0 0"/>      
      <geometry>        
        <mesh filename="package:///meshes/left_wrist_bearing_plate_collision.stl"/>        
      </geometry>      
    </collision>    
    <inertial>      
      <origin xyz="-0.0075835583121499931455 -0.015499999999999977338 -0.0018386323705903331437" rpy="0 0 0"/>      
      <mass value="0.0049000367468305557062"/>      
      <inertia ixx="4.970743010915013972e-07" ixy="1.1194558104431275937e-22" ixz="1.8100904820813988926e-08" iyy="7.1268523603538489532e-07" iyz="1.6072883979218723091e-23" izz="1.1919657811600100764e-06"/>      
    </inertial>    
  </link>  

  <joint name="left_wrist_pitch_fixed" type="fixed">    
    <origin xyz="0.015500000000005004566 -1.8207657603852567263e-14 -0.044999999999998596678" rpy="4.0494715863782802008e-14 -2.8209346585231002385e-13 -1.570796326794906328"/>    
    <parent link="2xl430_gears_3"/>    
    <child link="wrist_bearing_plate"/>    
    <axis xyz="0 0 1"/>    
    <limit effort="1" velocity="20"/>    
    <joint_properties friction="0.0"/>    
  </joint>  

  <joint name="left_wrist_pitch_driven" type="revolute">    
    <origin xyz="0 -3.9443045261050590271e-30 -0.0015999999999999972577" rpy="6.0387003530043805309e-16 -4.4981039962148287683e-16 -1.570796326794896558"/>    
    <parent link="spur_1m_24t_driven_3"/>    
    <child link="2xl430_gears_3"/>    
    <axis xyz="0 0 1"/>    
    <limit effort="1" velocity="20" lower="-1.3962634015954635824" upper="1.9198621771937625091"/>    
    <joint_properties friction="0.0"/>    
  </joint>  

  <joint name="left_wrist_roll_fixed" type="fixed">    
    <origin xyz="1.5777218104420236108e-30 -0.025300000000000006511 -0.05200000000000001843" rpy="1.5707963267949043296 -1.5707963267948885644 0"/>    
    <parent link="elb_yaw_link"/>    
    <child link="spur_1m_24t_driven_3"/>    
    <axis xyz="0 0 1"/>    
    <limit effort="1" velocity="20"/>    
    <joint_properties friction="0.0"/>    
  </joint>  

  <joint name="left_elbow_yaw_fixed" type="fixed">    
    <origin xyz="-1.5777218104420236108e-30 0 0.0016000000000000041966" rpy="-3.1415926535897873428 3.0591810185765374017e-29 0"/>    
    <parent link="spur_1m_24t_driven_2"/>    
    <child link="elb_yaw_link"/>    
    <axis xyz="0 0 1"/>    
    <limit effort="1" velocity="20"/>    
    <joint_properties friction="0.0"/>    
  </joint>  

  <joint name="left_elbow_yaw_driven" type="revolute">    
    <origin xyz="-3.5806251019732115992e-10 -0.027000000152458583647 -0.019000000000009956841" rpy="1.5707963267948450437 1.5707963267948292785 0"/>    
    <parent link="2xl430_gears_2"/>    
    <child link="spur_1m_24t_driven_2"/>    
    <axis xyz="0 0 1"/>    
    <limit effort="1" velocity="20" lower="-2.6179938779914944114" upper="2.6179938779914944114"/>    
    <joint_properties friction="0.0"/>    
  </joint>  

  <joint name="left_elbow_roll" type="revolute">    
    <origin xyz="-3.4694469519536141888e-18 -0.018999999999999999528 -0.059000000000000024647" rpy="1.570796326794896336 -5.3290705182069808708e-14 -2.456539448233997185e-14"/>    
    <parent link="sho_yaw_link"/>    
    <child link="2xl430_gears_2"/>    
    <axis xyz="0 0 1"/>    
    <limit effort="1" velocity="20" lower="-1.9198621771937625091" upper="2.4434609527920612138"/>    
    <joint_properties friction="0.0"/>    
  </joint>  

  <joint name="left_sho_yaw_fixed" type="fixed">    
    <origin xyz="3.4694469519536141888e-18 -9.8607613152626475676e-31 0.0015999999999999972577" rpy="3.141592653589793116 1.2621774483536197294e-29 4.7331654313260743357e-30"/>    
    <parent link="spur_1m_24t_driven"/>    
    <child link="sho_yaw_link"/>    
    <axis xyz="0 0 1"/>    
    <limit effort="1" velocity="20"/>    
    <joint_properties friction="0.0"/>    
  </joint>  

  <joint name="left_sho_yaw_driven" type="revolute">    
    <origin xyz="-3.5807158627054747058e-10 -0.02700000015245348009 -0.018999999999996589062" rpy="1.5707963267947120389 -1.3118271136488182808e-14 9.2981178312429448086e-14"/>    
    <parent link="2xl430_gears"/>    
    <child link="spur_1m_24t_driven"/>    
    <axis xyz="0 0 1"/>    
    <limit effort="1" velocity="20" lower="-2.6179938779914944114" upper="2.6179938779914944114"/>    
    <joint_properties friction="0.0"/>    
  </joint>  

  <joint name="left_sho_roll" type="revolute">    
    <origin xyz="-0.019000000000000016875 1.4231671397091401999e-17 0.027000000000000023981" rpy="-3.141592653589793116 1.5707963267948372721 0"/>    
    <parent link="sho_pitch_link"/>    
    <child link="2xl430_gears"/>    
    <axis xyz="0 0 1"/>    
    <limit effort="1" velocity="20" lower="-1.570796326794896558" upper="0.34906585039886589561"/>    
    <joint_properties friction="0.0"/>    
  </joint>  


</robot>