<?xml version="1.0" ?>
<mujoco model="sysID_2XL430">
  <compiler angle="radian" autolimits="true"/>
  <asset>
    <mesh name="2xl430_visual" file="../assemblies/sysID_2XL430/meshes/2xl430_visual.stl"/>
    <mesh name="arm_430_visual" file="../assemblies/sysID_2XL430/meshes/arm_430_visual.stl"/>
  </asset>
  <worldbody>
    <geom type="mesh" rgba="0.747742 0.840141 0.890015 1" mesh="2xl430_visual" class="visual"/>
    <body name="arm_430" pos="0.058 0.0326999 0.0056194" quat="0.5 0.5 -0.5 -0.5">
      <inertial pos="-0.0777904 1.36379e-05 -0.019" quat="0.706907 0 0 0.707306" mass="0.2555" diaginertia="0.000410739 0.000244261 0.000220842"/>
      <joint name="joint_0" pos="0 0 0" axis="0 0 1" range="-1.5708 1.5708" damping="0.12" armature="0.0042" frictionloss="0.292"/>
      <geom type="mesh" rgba="0.630593 0.65299 0.674189 1" mesh="arm_430_visual" class="visual"/>
    </body>
  </worldbody>
  <option>
    <flag eulerdamp="disable"/>
  </option>
  <equality/>
  <contact/>
  <actuator>
    <motor name="joint_0" joint="joint_0" class="2XL430"/>
  </actuator>
  <default>
    <default class="visual">
      <geom type="mesh" contype="0" conaffinity="0" group="2"/>
    </default>
    <default class="collision">
      <geom group="3"/>
    </default>
    <default class="2XL430">
      <motor ctrlrange="-2 2"/>
    </default>
  </default>
</mujoco>