<?xml version="1.0" ?><robot name="toddlerbot_active">  
  <link name="torso">    
    <visual>      
      <origin xyz="0 0 0" rpy="0 -0 0"/>      
      <geometry>        
        <mesh filename="package:///meshes/torso_visual.stl"/>        
      </geometry>      
      <material name="torso_material">        
        <color rgba="0.63866204066417398 0.79042612983052995546 0.89591918647189450198 1.0"/>        
      </material>      
    </visual>    
    <collision>      
      <origin xyz="0 0 0" rpy="0 -0 0"/>      
      <geometry>        
        <mesh filename="package:///meshes/torso_collision.stl"/>        
      </geometry>      
    </collision>    
    <inertial>      
      <origin xyz="-0.0025146157670445632749 -0.0034624525472092657248 0.065529395922090741267" rpy="0 0 0"/>      
      <mass value="1.085065963101202513"/>      
      <inertia ixx="0.0028272039396820135455" ixy="7.4126802941129236275e-05" ixz="1.8774159564660604415e-05" iyy="0.002249597677268255682" iyz="-2.9332579430689060759e-05" izz="0.0023020777581455841021"/>      
    </inertial>    
  </link>  

  <link name="spur_1m_20t">    
    <visual>      
      <origin xyz="0 0 0" rpy="0 -0 0"/>      
      <geometry>        
        <mesh filename="package:///meshes/spur_1m_20t_visual.stl"/>        
      </geometry>      
      <material name="spur_1m_20t_material">        
        <color rgba="0.64705882352941179736 0.64705882352941179736 0.64705882352941179736 1.0"/>        
      </material>      
    </visual>    
    <collision>      
      <origin xyz="0 0 0" rpy="0 -0 0"/>      
      <geometry>        
        <mesh filename="package:///meshes/spur_1m_20t_collision.stl"/>        
      </geometry>      
    </collision>    
    <inertial>      
      <origin xyz="-2.6272867535834243428e-19 -8.213876165191947908e-18 0.0033842321054344710884" rpy="0 0 0"/>      
      <mass value="0.0015778025963746002049"/>      
      <inertia ixx="4.5874424196602084909e-08" ixy="3.1120948173235942258e-24" ixz="-7.1097175513400468273e-39" iyy="4.5874424196602065057e-08" iyz="7.8419015231486123886e-38" izz="8.1737050837173876176e-08"/>      
    </inertial>    
  </link>  

  <joint name="neck_yaw_drive" type="fixed">    
    <origin xyz="-0.0049999999999995221878 3.1860588521011854095e-18 0.12148651076281755112" rpy="1.1607298201443905188e-14 1.6509758832059179101e-15 -5.3832337592600790636e-15"/>    
    <parent link="torso"/>    
    <child link="spur_1m_20t"/>    
    <axis xyz="0 0 1"/>    
    <limit effort="1" velocity="20"/>    
    <joint_properties friction="0.0"/>    
  </joint>  

  <link name="neck_yaw_link_v2">    
    <visual>      
      <origin xyz="0 0 0" rpy="0 -0 0"/>      
      <geometry>        
        <mesh filename="package:///meshes/neck_yaw_link_v2_visual.stl"/>        
      </geometry>      
      <material name="neck_yaw_link_v2_material">        
        <color rgba="0.2313725490196078538 0.38039215686274513439 0.7058823529411765163 1.0"/>        
      </material>      
    </visual>    
    <collision>      
      <origin xyz="0 0 0" rpy="0 -0 0"/>      
      <geometry>        
        <mesh filename="package:///meshes/neck_yaw_link_v2_collision.stl"/>        
      </geometry>      
    </collision>    
    <inertial>      
      <origin xyz="-1.1403990895340869883e-06 -1.1841855607304602894e-10 0.0082571849701004954719" rpy="0 0 0"/>      
      <mass value="0.0067298837334394097723"/>      
      <inertia ixx="5.2266067624768086445e-07" ixy="-6.3046403356094216415e-15" ixz="1.1949403084468002204e-09" iyy="6.1218519979556588152e-07" iyz="-2.601287198078358721e-15" izz="2.8062851709981924551e-07"/>      
    </inertial>    
  </link>  

  <link name="head">    
    <visual>      
      <origin xyz="0 0 0" rpy="0 -0 0"/>      
      <geometry>        
        <mesh filename="package:///meshes/head_visual.stl"/>        
      </geometry>      
      <material name="head_material">        
        <color rgba="0.62873939703496795062 0.79364291305093481732 0.87330110949792516539 1.0"/>        
      </material>      
    </visual>    
    <collision>      
      <origin xyz="0 0 0" rpy="0 -0 0"/>      
      <geometry>        
        <mesh filename="package:///meshes/head_collision.stl"/>        
      </geometry>      
    </collision>    
    <inertial>      
      <origin xyz="-0.045316002313821462932 -0.011276855645191820668 -0.0010251236602530952157" rpy="0 0 0"/>      
      <mass value="0.13722101760550839411"/>      
      <inertia ixx="0.00011880807294044733397" ixy="1.1390016804751257423e-06" ixz="1.8378816154934656445e-06" iyy="0.00010489076115433002847" iyz="-9.2536559812160233706e-06" izz="9.1894624061612226228e-05"/>      
    </inertial>    
  </link>  

  <link name="motor_plate">    
    <visual>      
      <origin xyz="0 0 0" rpy="0 -0 0"/>      
      <geometry>        
        <mesh filename="package:///meshes/motor_plate_visual.stl"/>        
      </geometry>      
      <material name="motor_plate_material">        
        <color rgba="0.64705882352941179736 0.64705882352941179736 0.64705882352941179736 1.0"/>        
      </material>      
    </visual>    
    <collision>      
      <origin xyz="0 0 0" rpy="0 -0 0"/>      
      <geometry>        
        <mesh filename="package:///meshes/motor_plate_collision.stl"/>        
      </geometry>      
    </collision>    
    <inertial>      
      <origin xyz="-6.9388939039072283776e-18 -3.4694469519536141888e-18 -0.0028281768943845498818" rpy="0 0 0"/>      
      <mass value="0.0016999999999999999053"/>      
      <inertia ixx="4.805029073310371698e-08" ixy="1.0773753257370483397e-09" ixz="-2.8434898612727714968e-36" iyy="5.1782428339099030199e-08" iyz="-8.7187946076336322982e-37" izz="9.2194729037862249329e-08"/>      
    </inertial>    
  </link>  

  <joint name="neck_pitch_act" type="fixed">    
    <origin xyz="-0.032615697718560709983 -0.027000000000000072553 0.0024999999999998486974" rpy="-3.1415926535897655825 -3.1793530896719215746e-13 -3.1415926535897407135"/>    
    <parent link="head"/>    
    <child link="motor_plate"/>    
    <axis xyz="0 0 1"/>    
    <limit effort="1" velocity="20"/>    
    <joint_properties friction="0.0"/>    
  </joint>  

  <joint name="neck_pitch" type="revolute">    
    <origin xyz="-1.1796119636642288242e-16 0.0040000000000001215139 0.019400000000000056088" rpy="-1.5707963267904627713 1.5671692223466835436 -3.1415926535886637971"/>    
    <parent link="neck_yaw_link_v2"/>    
    <child link="head"/>    
    <axis xyz="0 0 1"/>    
    <limit effort="1" velocity="20" lower="-1.3962634015954635824" upper="0.61086523819801530344"/>    
    <joint_properties friction="0.0"/>    
  </joint>  

  <joint name="neck_yaw" type="revolute">    
    <origin xyz="0.016000000000000621364 3.9122381713629107253e-19 0.12248651076281739936" rpy="1.5470695466536949876e-14 -3.0902695541116811913e-15 -8.6007558735577539147e-16"/>    
    <parent link="torso"/>    
    <child link="neck_yaw_link_v2"/>    
    <axis xyz="0 0 1"/>    
    <limit effort="1" velocity="20" lower="-2.6179938779914944114" upper="2.6179938779914944114"/>    
    <joint_properties friction="0.0"/>    
  </joint>  

  <link name="waist_gears">    
    <visual>      
      <origin xyz="0 0 0" rpy="0 -0 0"/>      
      <geometry>        
        <mesh filename="package:///meshes/waist_gears_visual.stl"/>        
      </geometry>      
      <material name="waist_gears_material">        
        <color rgba="0.29673072126509869584 0.50090014891145373532 0.63316042503557945498 1.0"/>        
      </material>      
    </visual>    
    <collision>      
      <origin xyz="0 0 0" rpy="0 -0 0"/>      
      <geometry>        
        <mesh filename="package:///meshes/waist_gears_collision.stl"/>        
      </geometry>      
    </collision>    
    <inertial>      
      <origin xyz="-2.9089024308857832571e-07 5.5035553748624927846e-08 -0.012592985430860506244" rpy="0 0 0"/>      
      <mass value="0.026337180140419177987"/>      
      <inertia ixx="1.5367047941033414761e-06" ixy="1.8828487083154202092e-11" ixz="4.0600521957505171123e-10" iyy="7.3024712275450681231e-06" iyz="3.2911737857356925833e-12" izz="6.9859065635059629397e-06"/>      
    </inertial>    
  </link>  

  <link name="waist_link">    
    <visual>      
      <origin xyz="0 0 0" rpy="0 -0 0"/>      
      <geometry>        
        <mesh filename="package:///meshes/waist_link_visual.stl"/>        
      </geometry>      
      <material name="waist_link_material">        
        <color rgba="0.64205964988973118768 0.77112878115803895618 0.80455743168009175026 1.0"/>        
      </material>      
    </visual>    
    <collision>      
      <origin xyz="0 0 0" rpy="0 -0 0"/>      
      <geometry>        
        <mesh filename="package:///meshes/waist_link_collision.stl"/>        
      </geometry>      
    </collision>    
    <inertial>      
      <origin xyz="-1.8696422424380786576e-17 -0.024647143936899634092 -0.024243097328499933762" rpy="0 0 0"/>      
      <mass value="0.10819999998618363979"/>      
      <inertia ixx="4.7479700735674147856e-05" ixy="-2.3251323235829624041e-20" ixz="-5.6250747314438694771e-09" iyy="9.6352172992785761079e-05" iyz="1.5514215856085537166e-06" izz="6.7249246473032378828e-05"/>      
    </inertial>    
  </link>  

  <link name="spiral_bevel_1m_14t_30deg">    
    <visual>      
      <origin xyz="0 0 0" rpy="0 -0 0"/>      
      <geometry>        
        <mesh filename="package:///meshes/spiral_bevel_1m_14t_30deg_visual.stl"/>        
      </geometry>      
      <material name="spiral_bevel_1m_14t_30deg_material">        
        <color rgba="0.64705882352941179736 0.64705882352941179736 0.64705882352941179736 1.0"/>        
      </material>      
    </visual>    
    <collision>      
      <origin xyz="0 0 0" rpy="0 -0 0"/>      
      <geometry>        
        <mesh filename="package:///meshes/spiral_bevel_1m_14t_30deg_collision.stl"/>        
      </geometry>      
    </collision>    
    <inertial>      
      <origin xyz="7.4971447105998133901e-10 7.1802237332913011122e-10 0.0066868955018979173155" rpy="0 0 0"/>      
      <mass value="0.00073261524436595492574"/>      
      <inertia ixx="1.3495056019478195011e-08" ixy="4.0596681291792787018e-17" ixz="8.5992550177701704034e-16" iyy="1.3495056150237195634e-08" iyz="-6.7913008238986341959e-16" izz="1.43559865498164051e-08"/>      
    </inertial>    
  </link>  

  <joint name="waist_act_1" type="fixed">    
    <origin xyz="-4.2595620045002374081e-18 -0.019600000000000006306 -0.012749999999999992242" rpy="1.570796326794896558 -1.1294754804497596673e-16 3.1415926535897926719"/>    
    <parent link="waist_link"/>    
    <child link="spiral_bevel_1m_14t_30deg"/>    
    <axis xyz="0 0 1"/>    
    <limit effort="1" velocity="20"/>    
    <joint_properties friction="0.0"/>    
  </joint>  

  <link name="spiral_bevel_1m_14t_30deg_2">    
    <visual>      
      <origin xyz="0 0 0" rpy="0 -0 0"/>      
      <geometry>        
        <mesh filename="package:///meshes/spiral_bevel_1m_14t_30deg_2_visual.stl"/>        
      </geometry>      
      <material name="spiral_bevel_1m_14t_30deg_2_material">        
        <color rgba="0.64705882352941179736 0.64705882352941179736 0.64705882352941179736 1.0"/>        
      </material>      
    </visual>    
    <collision>      
      <origin xyz="0 0 0" rpy="0 -0 0"/>      
      <geometry>        
        <mesh filename="package:///meshes/spiral_bevel_1m_14t_30deg_2_collision.stl"/>        
      </geometry>      
    </collision>    
    <inertial>      
      <origin xyz="3.6393116992217144912e-10 -9.7220472687967185443e-10 -0.0066868955018979190502" rpy="0 0 0"/>      
      <mass value="0.00073261524436595492574"/>      
      <inertia ixx="1.3495056012354480834e-08" ixy="2.5804135489187712274e-17" ixz="-1.069429605266726274e-15" iyy="1.3495056157360909811e-08" iyz="-2.387673694220831759e-16" izz="1.4355986549816408408e-08"/>      
    </inertial>    
  </link>  

  <joint name="waist_act_2" type="fixed">    
    <origin xyz="1.2028779959866843989e-17 -0.019599999999999999367 -0.032750000000000001332" rpy="-1.570796326794896558 1.1469143902292295508e-17 -3.141592653589793116"/>    
    <parent link="waist_link"/>    
    <child link="spiral_bevel_1m_14t_30deg_2"/>    
    <axis xyz="0 0 1"/>    
    <limit effort="1" velocity="20"/>    
    <joint_properties friction="0.0"/>    
  </joint>  

  <link name="left_leg_active">    
    <visual>      
      <origin xyz="0 0 0" rpy="0 -0 0"/>      
      <geometry>        
        <mesh filename="package:///meshes/left_leg_active_visual.stl"/>        
      </geometry>      
      <material name="left_leg_active_material">        
        <color rgba="0.67835035434534174392 0.664565314370153426 0.49955906843423497632 1.0"/>        
      </material>      
    </visual>    
    <collision>      
      <origin xyz="0 0 0" rpy="0 -0 0"/>      
      <geometry>        
        <mesh filename="package:///meshes/left_leg_active_collision.stl"/>        
      </geometry>      
    </collision>    
    <inertial>      
      <origin xyz="-0.14092425877841704973 0.0077365634042377640425 0.017464576249293012333" rpy="0 0 0"/>      
      <mass value="0.52921784862573284514"/>      
      <inertia ixx="0.00027159349071758195253" ixy="0.00012975665444408371915" ixz="4.4692420290224279676e-05" iyy="0.0046945349426157695003" iyz="2.4210259476750212908e-06" izz="0.0048508184546251715066"/>      
    </inertial>    
  </link>  

  <joint name="left_hip_pitch" type="revolute">    
    <origin xyz="0.05600000000000003586 -0.040100000000000766975 -0.02275000000000062389" rpy="-1.570796326794896558 2.3372262395059397709e-15 1.5707963267948974462"/>    
    <parent link="waist_link"/>    
    <child link="left_leg_active"/>    
    <axis xyz="0 0 1"/>    
    <limit effort="1" velocity="20" lower="-1.570796326794896558" upper="2.356194490192344837"/>    
    <joint_properties friction="0.0"/>    
  </joint>  

  <link name="right_leg_active">    
    <visual>      
      <origin xyz="0 0 0" rpy="0 -0 0"/>      
      <geometry>        
        <mesh filename="package:///meshes/right_leg_active_visual.stl"/>        
      </geometry>      
      <material name="right_leg_active_material">        
        <color rgba="0.67876327671658420737 0.66359535004692016269 0.49672657180944773669 1.0"/>        
      </material>      
    </visual>    
    <collision>      
      <origin xyz="0 0 0" rpy="0 -0 0"/>      
      <geometry>        
        <mesh filename="package:///meshes/right_leg_active_collision.stl"/>        
      </geometry>      
    </collision>    
    <inertial>      
      <origin xyz="-0.14116534832532304233 -0.0075848241194076508609 0.017478255614581609395" rpy="0 0 0"/>      
      <mass value="0.52575341814690124131"/>      
      <inertia ixx="0.00027208293955285965497" ixy="-0.000142807757240519614" ixz="4.4517445869087677527e-05" iyy="0.00468709591741410872" iyz="-3.8190578771648266574e-06" izz="0.0048443980856464063933"/>      
    </inertial>    
  </link>  

  <joint name="right_hip_pitch" type="revolute">    
    <origin xyz="-0.055999999999999966471 -0.040099999999999282052 -0.022750000000000037553" rpy="1.57079632679489678 3.8857805862892459266e-16 1.5707963267948961139"/>    
    <parent link="waist_link"/>    
    <child link="right_leg_active"/>    
    <axis xyz="0 0 1"/>    
    <limit effort="1" velocity="20" lower="-2.356194490192344837" upper="1.570796326794896558"/>    
    <joint_properties friction="0.0"/>    
  </joint>  

  <joint name="waist_roll" type="revolute">    
    <origin xyz="-0.022707865260692423198 -9.7274600111297846042e-19 -0.014000000000000000291" rpy="1.570796326794896558 8.4288122184796088386e-16 -1.570796326794896558"/>    
    <parent link="waist_gears"/>    
    <child link="waist_link"/>    
    <axis xyz="0 0 1"/>    
    <limit effort="1" velocity="20" lower="-0.52359877559829881566" upper="0.52359877559829881566"/>    
    <joint_properties friction="0.0"/>    
  </joint>  

  <joint name="waist_yaw" type="revolute">    
    <origin xyz="0 2.3419308123748787973e-31 -2.4651903288156618919e-32" rpy="1.7541622236939310179e-17 -3.9276012762146508757e-15 3.1415926535897922278"/>    
    <parent link="torso"/>    
    <child link="waist_gears"/>    
    <axis xyz="0 0 1"/>    
    <limit effort="1" velocity="20" lower="-1.570796326794896558" upper="1.570796326794896558"/>    
    <joint_properties friction="0.0"/>    
  </joint>  

  <link name="left_arm_active">    
    <visual>      
      <origin xyz="0 0 0" rpy="0 -0 0"/>      
      <geometry>        
        <mesh filename="package:///meshes/left_arm_active_visual.stl"/>        
      </geometry>      
      <material name="left_arm_active_material">        
        <color rgba="0.72341525389597438611 0.82443744477834624007 0.88223563844125418854 1.0"/>        
      </material>      
    </visual>    
    <collision>      
      <origin xyz="0 0 0" rpy="0 -0 0"/>      
      <geometry>        
        <mesh filename="package:///meshes/left_arm_active_collision.stl"/>        
      </geometry>      
    </collision>    
    <inertial>      
      <origin xyz="-0.00016036435969828059908 0.095083207758240154139 0.03394084089040318164" rpy="0 0 0"/>      
      <mass value="0.45670014698257832553"/>      
      <inertia ixx="0.0023660873890197224763" ixy="-7.3963929048819939324e-06" ixz="1.2562640552599602809e-07" iyy="0.00016046488915592976572" iyz="8.7828546788881899543e-05" izz="0.0023335501993751606858"/>      
    </inertial>    
  </link>  

  <joint name="left_sho_pitch" type="revolute">    
    <origin xyz="-0.0035000000000004762545 0.067000000000001072586 0.10423651076281729988" rpy="-1.5707963267949092145 -4.1276434099564722448e-14 3.4723733359247937182e-14"/>    
    <parent link="torso"/>    
    <child link="left_arm_active"/>    
    <axis xyz="0 0 1"/>    
    <limit effort="1" velocity="20" lower="-3.141592653589793116" upper="1.570796326794896558"/>    
    <joint_properties friction="0.0"/>    
  </joint>  

  <link name="right_arm_active">    
    <visual>      
      <origin xyz="0 0 0" rpy="0 -0 0"/>      
      <geometry>        
        <mesh filename="package:///meshes/right_arm_active_visual.stl"/>        
      </geometry>      
      <material name="right_arm_active_material">        
        <color rgba="0.72341525389597460816 0.82443744477834646212 0.88223563844125429956 1.0"/>        
      </material>      
    </visual>    
    <collision>      
      <origin xyz="0 0 0" rpy="0 -0 0"/>      
      <geometry>        
        <mesh filename="package:///meshes/right_arm_active_collision.stl"/>        
      </geometry>      
    </collision>    
    <inertial>      
      <origin xyz="-7.1603222576714910751e-05 0.095083207758231910733 0.033940840890699569554" rpy="0 0 0"/>      
      <mass value="0.45670014698257821451"/>      
      <inertia ixx="0.0023660873890183719941" ixy="-1.2149368780260271124e-05" ixz="9.4880455659918878647e-08" iyy="0.00016047429247689865245" iyz="8.7828546774973510129e-05" izz="0.0023335596026967009471"/>      
    </inertial>    
  </link>  

  <joint name="right_sho_pitch" type="revolute">    
    <origin xyz="-0.003499999999998689923 -0.067000000000001017075 0.10423651076281729988" rpy="-1.5707963267948874542 3.6375999989622199756e-14 -3.1415926535897562566"/>    
    <parent link="torso"/>    
    <child link="right_arm_active"/>    
    <axis xyz="0 0 1"/>    
    <limit effort="1" velocity="20" lower="-1.570796326794896558" upper="3.141592653589793116"/>    
    <joint_properties friction="0.0"/>    
  </joint>  


</robot>