<?xml version="1.0" ?>
<robot name="toddlerbot_active">
  <mujoco>
    <compiler strippath="false" balanceinertia="true" discardvisual="false"/>
  </mujoco>
  <link name="torso">
    <visual>
      <origin xyz="0 0 0" rpy="0 -0 0"/>
      <geometry>
        <mesh filename="../assemblies/toddlerbot_active/meshes/torso_visual.stl"/>
      </geometry>
      <material name="torso_material">
        <color rgba="0.63866204066417398 0.79042612983052995546 0.89591918647189450198 1.0"/>
      </material>
    </visual>
    <collision name="torso_collision">
      <origin xyz="-0.02850000374019146 -5.000084638595581e-05 0.07068824046291411" rpy="0 0 0"/>
      <geometry>
        <box size="0.14100000634789467 0.13759998977184296 0.1454972173087299"/>
      </geometry>
    </collision>
    <inertial>
      <origin xyz="-0.0025146157670445632749 -0.0034624525472092657248 0.065529395922090741267" rpy="0 0 0"/>
      <mass value="1.085065963101202513"/>
      <inertia ixx="0.0028272039396820135455" ixy="7.4126802941129236275e-05" ixz="1.8774159564660604415e-05" iyy="0.002249597677268255682" iyz="-2.9332579430689060759e-05" izz="0.0023020777581455841021"/>
    </inertial>
  </link>
  <link name="spur_1m_20t">
    <visual>
      <origin xyz="0 0 0" rpy="0 -0 0"/>
      <geometry>
        <mesh filename="../assemblies/toddlerbot_active/meshes/spur_1m_20t_visual.stl"/>
      </geometry>
      <material name="spur_1m_20t_material">
        <color rgba="0.64705882352941179736 0.64705882352941179736 0.64705882352941179736 1.0"/>
      </material>
    </visual>
    <inertial>
      <origin xyz="-2.6272867535834243428e-19 -8.213876165191947908e-18 0.0033842321054344710884" rpy="0 0 0"/>
      <mass value="0.0015778025963746002049"/>
      <inertia ixx="4.5874424196602084909e-08" ixy="3.1120948173235942258e-24" ixz="-7.1097175513400468273e-39" iyy="4.5874424196602065057e-08" iyz="7.8419015231486123886e-38" izz="8.1737050837173876176e-08"/>
    </inertial>
  </link>
  <joint name="neck_yaw_drive" type="fixed">
    <origin xyz="-0.0049999999999995221878 3.1860588521011854095e-18 0.12148651076281755112" rpy="1.1607298201443905188e-14 1.6509758832059179101e-15 -5.3832337592600790636e-15"/>
    <parent link="torso"/>
    <child link="spur_1m_20t"/>
    <axis xyz="0 0 1"/>
    <limit effort="1" velocity="20"/>
    <joint_properties friction="0.0"/>
  </joint>
  <link name="neck_yaw_link_v2">
    <visual>
      <origin xyz="0 0 0" rpy="0 -0 0"/>
      <geometry>
        <mesh filename="../assemblies/toddlerbot_active/meshes/neck_yaw_link_v2_visual.stl"/>
      </geometry>
      <material name="neck_yaw_link_v2_material">
        <color rgba="0.2313725490196078538 0.38039215686274513439 0.7058823529411765163 1.0"/>
      </material>
    </visual>
    <inertial>
      <origin xyz="-1.1403990895340869883e-06 -1.1841855607304602894e-10 0.0082571849701004954719" rpy="0 0 0"/>
      <mass value="0.0067298837334394097723"/>
      <inertia ixx="5.2266067624768086445e-07" ixy="-6.3046403356094216415e-15" ixz="1.1949403084468002204e-09" iyy="6.1218519979556588152e-07" iyz="-2.601287198078358721e-15" izz="2.8062851709981924551e-07"/>
    </inertial>
  </link>
  <link name="head">
    <visual>
      <origin xyz="0 0 0" rpy="0 -0 0"/>
      <geometry>
        <mesh filename="../assemblies/toddlerbot_active/meshes/head_visual.stl"/>
      </geometry>
      <material name="head_material">
        <color rgba="0.62873939703496795062 0.79364291305093481732 0.87330110949792516539 1.0"/>
      </material>
    </visual>
    <inertial>
      <origin xyz="-0.045316002313821462932 -0.011276855645191820668 -0.0010251236602530952157" rpy="0 0 0"/>
      <mass value="0.13722101760550839411"/>
      <inertia ixx="0.00011880807294044733397" ixy="1.1390016804751257423e-06" ixz="1.8378816154934656445e-06" iyy="0.00010489076115433002847" iyz="-9.2536559812160233706e-06" izz="9.1894624061612226228e-05"/>
    </inertial>
  </link>
  <link name="motor_plate">
    <visual>
      <origin xyz="0 0 0" rpy="0 -0 0"/>
      <geometry>
        <mesh filename="../assemblies/toddlerbot_active/meshes/motor_plate_visual.stl"/>
      </geometry>
      <material name="motor_plate_material">
        <color rgba="0.64705882352941179736 0.64705882352941179736 0.64705882352941179736 1.0"/>
      </material>
    </visual>
    <inertial>
      <origin xyz="-6.9388939039072283776e-18 -3.4694469519536141888e-18 -0.0028281768943845498818" rpy="0 0 0"/>
      <mass value="0.0016999999999999999053"/>
      <inertia ixx="4.805029073310371698e-08" ixy="1.0773753257370483397e-09" ixz="-2.8434898612727714968e-36" iyy="5.1782428339099030199e-08" iyz="-8.7187946076336322982e-37" izz="9.2194729037862249329e-08"/>
    </inertial>
  </link>
  <joint name="neck_pitch_act" type="fixed">
    <origin xyz="-0.032615697718560709983 -0.027000000000000072553 0.0024999999999998486974" rpy="-3.1415926535897655825 -3.1793530896719215746e-13 -3.1415926535897407135"/>
    <parent link="head"/>
    <child link="motor_plate"/>
    <axis xyz="0 0 1"/>
    <limit effort="1" velocity="20"/>
    <joint_properties friction="0.0"/>
  </joint>
  <joint name="neck_pitch" type="revolute">
    <origin xyz="-1.1796119636642288242e-16 0.0040000000000001215139 0.019400000000000056088" rpy="-1.5707963267904627713 1.5671692223466835436 -3.1415926535886637971"/>
    <parent link="neck_yaw_link_v2"/>
    <child link="head"/>
    <axis xyz="0 0 1"/>
    <limit effort="1" velocity="20" lower="-1.3962634015954635824" upper="0.61086523819801530344"/>
    <joint_properties friction="0.0"/>
  </joint>
  <joint name="neck_yaw" type="revolute">
    <origin xyz="0.016000000000000621364 3.9122381713629107253e-19 0.12248651076281739936" rpy="1.5470695466536949876e-14 -3.0902695541116811913e-15 -8.6007558735577539147e-16"/>
    <parent link="torso"/>
    <child link="neck_yaw_link_v2"/>
    <axis xyz="0 0 1"/>
    <limit effort="1" velocity="20" lower="-2.6179938779914944114" upper="2.6179938779914944114"/>
    <joint_properties friction="0.0"/>
  </joint>
  <link name="waist_gears">
    <visual>
      <origin xyz="0 0 0" rpy="0 -0 0"/>
      <geometry>
        <mesh filename="../assemblies/toddlerbot_active/meshes/waist_gears_visual.stl"/>
      </geometry>
      <material name="waist_gears_material">
        <color rgba="0.29673072126509869584 0.50090014891145373532 0.63316042503557945498 1.0"/>
      </material>
    </visual>
    <inertial>
      <origin xyz="-2.9089024308857832571e-07 5.5035553748624927846e-08 -0.012592985430860506244" rpy="0 0 0"/>
      <mass value="0.026337180140419177987"/>
      <inertia ixx="1.5367047941033414761e-06" ixy="1.8828487083154202092e-11" ixz="4.0600521957505171123e-10" iyy="7.3024712275450681231e-06" iyz="3.2911737857356925833e-12" izz="6.9859065635059629397e-06"/>
    </inertial>
  </link>
  <link name="waist_link">
    <visual>
      <origin xyz="0 0 0" rpy="0 -0 0"/>
      <geometry>
        <mesh filename="../assemblies/toddlerbot_active/meshes/waist_link_visual.stl"/>
      </geometry>
      <material name="waist_link_material">
        <color rgba="0.64205964988973118768 0.77112878115803895618 0.80455743168009175026 1.0"/>
      </material>
    </visual>
    <collision name="waist_link_collision">
      <origin xyz="0.0 -0.021850000135600567 -0.022750000469386578" rpy="0 0 0"/>
      <geometry>
        <box size="0.11999999731779099 0.057499999180436134 0.07000000216066837"/>
      </geometry>
    </collision>
    <inertial>
      <origin xyz="-1.8696422424380786576e-17 -0.024647143936899634092 -0.024243097328499933762" rpy="0 0 0"/>
      <mass value="0.10819999998618363979"/>
      <inertia ixx="4.7479700735674147856e-05" ixy="-2.3251323235829624041e-20" ixz="-5.6250747314438694771e-09" iyy="9.6352172992785761079e-05" iyz="1.5514215856085537166e-06" izz="6.7249246473032378828e-05"/>
    </inertial>
  </link>
  <link name="spiral_bevel_1m_14t_30deg">
    <visual>
      <origin xyz="0 0 0" rpy="0 -0 0"/>
      <geometry>
        <mesh filename="../assemblies/toddlerbot_active/meshes/spiral_bevel_1m_14t_30deg_visual.stl"/>
      </geometry>
      <material name="spiral_bevel_1m_14t_30deg_material">
        <color rgba="0.64705882352941179736 0.64705882352941179736 0.64705882352941179736 1.0"/>
      </material>
    </visual>
    <inertial>
      <origin xyz="7.4971447105998133901e-10 7.1802237332913011122e-10 0.0066868955018979173155" rpy="0 0 0"/>
      <mass value="0.00073261524436595492574"/>
      <inertia ixx="1.3495056019478195011e-08" ixy="4.0596681291792787018e-17" ixz="8.5992550177701704034e-16" iyy="1.3495056150237195634e-08" iyz="-6.7913008238986341959e-16" izz="1.43559865498164051e-08"/>
    </inertial>
  </link>
  <joint name="waist_act_1" type="fixed">
    <origin xyz="-4.2595620045002374081e-18 -0.019600000000000006306 -0.012749999999999992242" rpy="1.570796326794896558 -1.1294754804497596673e-16 3.1415926535897926719"/>
    <parent link="waist_link"/>
    <child link="spiral_bevel_1m_14t_30deg"/>
    <axis xyz="0 0 1"/>
    <limit effort="1" velocity="20"/>
    <joint_properties friction="0.0"/>
  </joint>
  <link name="spiral_bevel_1m_14t_30deg_2">
    <visual>
      <origin xyz="0 0 0" rpy="0 -0 0"/>
      <geometry>
        <mesh filename="../assemblies/toddlerbot_active/meshes/spiral_bevel_1m_14t_30deg_2_visual.stl"/>
      </geometry>
      <material name="spiral_bevel_1m_14t_30deg_2_material">
        <color rgba="0.64705882352941179736 0.64705882352941179736 0.64705882352941179736 1.0"/>
      </material>
    </visual>
    <inertial>
      <origin xyz="3.6393116992217144912e-10 -9.7220472687967185443e-10 -0.0066868955018979190502" rpy="0 0 0"/>
      <mass value="0.00073261524436595492574"/>
      <inertia ixx="1.3495056012354480834e-08" ixy="2.5804135489187712274e-17" ixz="-1.069429605266726274e-15" iyy="1.3495056157360909811e-08" iyz="-2.387673694220831759e-16" izz="1.4355986549816408408e-08"/>
    </inertial>
  </link>
  <joint name="waist_act_2" type="fixed">
    <origin xyz="1.2028779959866843989e-17 -0.019599999999999999367 -0.032750000000000001332" rpy="-1.570796326794896558 1.1469143902292295508e-17 -3.141592653589793116"/>
    <parent link="waist_link"/>
    <child link="spiral_bevel_1m_14t_30deg_2"/>
    <axis xyz="0 0 1"/>
    <limit effort="1" velocity="20"/>
    <joint_properties friction="0.0"/>
  </joint>
  <joint name="left_hip_pitch" type="revolute">
    <origin xyz="0.05600000000000003586 -0.040100000000000766975 -0.02275000000000062389" rpy="-1.570796326794896558 2.3372262395059397709e-15 1.5707963267948974462"/>
    <parent link="waist_link"/>
    <child link="2xc430"/>
    <axis xyz="0 0 1"/>
    <limit effort="1" velocity="20" lower="-1.570796326794896558" upper="2.356194490192344837"/>
    <joint_properties friction="0.0"/>
  </joint>
  <joint name="right_hip_pitch" type="revolute">
    <origin xyz="-0.055999999999999966471 -0.040099999999999282052 -0.022750000000000037553" rpy="1.57079632679489678 3.8857805862892459266e-16 1.5707963267948961139"/>
    <parent link="waist_link"/>
    <child link="2xc430_2"/>
    <axis xyz="0 0 1"/>
    <limit effort="1" velocity="20" lower="-2.356194490192344837" upper="1.570796326794896558"/>
    <joint_properties friction="0.0"/>
  </joint>
  <joint name="waist_roll" type="revolute">
    <origin xyz="-0.022707865260692423198 -9.7274600111297846042e-19 -0.014000000000000000291" rpy="1.570796326794896558 8.4288122184796088386e-16 -1.570796326794896558"/>
    <parent link="waist_gears"/>
    <child link="waist_link"/>
    <axis xyz="0 0 1"/>
    <limit effort="1" velocity="20" lower="-0.52359877559829881566" upper="0.52359877559829881566"/>
    <joint_properties friction="0.0"/>
  </joint>
  <joint name="waist_yaw" type="revolute">
    <origin xyz="0 2.3419308123748787973e-31 -2.4651903288156618919e-32" rpy="1.7541622236939310179e-17 -3.9276012762146508757e-15 3.1415926535897922278"/>
    <parent link="torso"/>
    <child link="waist_gears"/>
    <axis xyz="0 0 1"/>
    <limit effort="1" velocity="20" lower="-1.570796326794896558" upper="1.570796326794896558"/>
    <joint_properties friction="0.0"/>
  </joint>
  <joint name="left_sho_pitch" type="revolute">
    <origin xyz="-0.0035000000000004762545 0.067000000000001072586 0.10423651076281729988" rpy="-1.5707963267949092145 -4.1276434099564722448e-14 3.4723733359247937182e-14"/>
    <parent link="torso"/>
    <child link="sho_pitch_link"/>
    <axis xyz="0 0 1"/>
    <limit effort="1" velocity="20" lower="-3.141592653589793116" upper="1.570796326794896558"/>
    <joint_properties friction="0.0"/>
  </joint>
  <joint name="right_sho_pitch" type="revolute">
    <origin xyz="-0.003499999999998689923 -0.067000000000001017075 0.10423651076281729988" rpy="-1.5707963267948874542 3.6375999989622199756e-14 -3.1415926535897562566"/>
    <parent link="torso"/>
    <child link="sho_pitch_link_2"/>
    <axis xyz="0 0 1"/>
    <limit effort="1" velocity="20" lower="-1.570796326794896558" upper="3.141592653589793116"/>
    <joint_properties friction="0.0"/>
  </joint>
  <link name="2xc430">
    <visual>
      <origin xyz="0 0 0" rpy="0 -0 0"/>
      <geometry>
        <mesh filename="../assemblies/left_leg_active/meshes/left_2xc430_visual.stl"/>
      </geometry>
      <material name="2xc430_material">
        <color rgba="0.51698661238356047321 0.50347815951093488618 0.49050589017722012741 1.0"/>
      </material>
    </visual>
    <inertial>
      <origin xyz="-0.0120001511339564923 0.00049588831385626367092 0.01850401924450319896" rpy="0 0 0"/>
      <mass value="0.11059999999836234164"/>
      <inertia ixx="2.2818802599017385101e-05" ixy="4.6888548258345894655e-08" ixz="4.6520143289217505514e-08" iyy="3.0871666424467696587e-05" iyz="-5.7477343899723834052e-07" izz="3.0871632082336744173e-05"/>
    </inertial>
  </link>
  <link name="hip_yaw_link">
    <visual>
      <origin xyz="0 0 0" rpy="0 -0 0"/>
      <geometry>
        <mesh filename="../assemblies/left_leg_active/meshes/left_hip_yaw_link_visual.stl"/>
      </geometry>
      <material name="hip_yaw_link_material">
        <color rgba="0.61568627450980395466 0.81176470588235294379 0.92941176470588238168 1.0"/>
      </material>
    </visual>
    <inertial>
      <origin xyz="7.9056415076153557052e-19 -0.015800610849654277146 -0.019005670096647751116" rpy="0 0 0"/>
      <mass value="0.013199999999999992989"/>
      <inertia ixx="5.789461597517412337e-06" ixy="-1.7415088674758894312e-36" ixz="1.2832779283935135522e-36" iyy="5.0110144042848776317e-06" iyz="1.1826010760651176287e-09" izz="2.7344876354814331659e-06"/>
    </inertial>
  </link>
  <link name="spur_gear_21_teeth">
    <visual>
      <origin xyz="0 0 0" rpy="0 -0 0"/>
      <geometry>
        <mesh filename="../assemblies/left_leg_active/meshes/left_spur_gear_21_teeth_visual.stl"/>
      </geometry>
      <material name="spur_gear_21_teeth_material">
        <color rgba="0.61568627450980395466 0.81176470588235294379 0.9294117647058824927 1.0"/>
      </material>
    </visual>
    <inertial>
      <origin xyz="-4.5505289335411606329e-11 -1.6782163661890817574e-11 -0.00249241020062506086" rpy="0 0 0"/>
      <mass value="0.0022000000000000001325"/>
      <inertia ixx="7.0162310059594196881e-08" ixy="-1.7296344820489596811e-39" ixz="-2.6465015955880150586e-39" iyy="7.016231005804746178e-08" iyz="4.706443675885446204e-39" izz="1.3125544198538289306e-07"/>
    </inertial>
  </link>
  <link name="left_hip_pitch_link">
    <visual>
      <origin xyz="0 0 0" rpy="0 -0 0"/>
      <geometry>
        <mesh filename="../assemblies/left_leg_active/meshes/left_hip_pitch_link_visual.stl"/>
      </geometry>
      <material name="left_hip_pitch_link_material">
        <color rgba="0.80773802221328794282 0.71541030077254164077 0.35058406659986895981 1.0"/>
      </material>
    </visual>
    <collision name="left_hip_pitch_link_collision">
      <origin xyz="-0.009275000542402267 -0.004349999129772186 0.05247500166296959" rpy="0 0 0"/>
      <geometry>
        <box size="0.05855000019073486 0.042399998754262924 0.10495000332593918"/>
      </geometry>
    </collision>
    <inertial>
      <origin xyz="-0.0099310748247876320938 -0.0055733268638736314579 0.039014117054800595552" rpy="0 0 0"/>
      <mass value="0.14895408167669133004"/>
      <inertia ixx="7.3955327919483632962e-05" ixy="-1.1805488631452789334e-06" ixz="-8.060325155229058482e-06" iyy="8.8995102919696593489e-05" iyz="1.1275669888575771416e-06" izz="4.2292269256454298725e-05"/>
    </inertial>
  </link>
  <link name="spur_gear_18_teeth">
    <visual>
      <origin xyz="0 0 0" rpy="0 -0 0"/>
      <geometry>
        <mesh filename="../assemblies/left_leg_active/meshes/left_spur_gear_18_teeth_visual.stl"/>
      </geometry>
      <material name="spur_gear_18_teeth_material">
        <color rgba="0.61568627450980395466 0.81176470588235294379 0.92941176470588238168 1.0"/>
      </material>
    </visual>
    <inertial>
      <origin xyz="-7.7513419666719815872e-14 -3.6849749222242637987e-13 0.0017500000000010135486" rpy="0 0 0"/>
      <mass value="0.0011999999999999998949"/>
      <inertia ixx="2.9367899810799927978e-08" ixy="7.0237994118966961071e-19" ixz="-9.093083600898419224e-36" iyy="2.9367899814659469999e-08" iyz="-6.7496912845597021962e-37" izz="5.6306346207859581581e-08"/>
    </inertial>
  </link>
  <joint name="left_hip_yaw_drive" type="fixed">
    <origin xyz="-0.019199999999993326572 0.00020000000000297904479 -3.3591185388814892576e-14" rpy="-3.1415926535896656624 -5.0119741105083928872e-13 4.8264601989417384549e-13"/>
    <parent link="left_hip_pitch_link"/>
    <child link="spur_gear_18_teeth"/>
    <axis xyz="0 0 1"/>
    <limit effort="1" velocity="20"/>
    <joint_properties friction="0.0"/>
  </joint>
  <link name="left_calf_link">
    <visual>
      <origin xyz="0 0 0" rpy="0 -0 0"/>
      <geometry>
        <mesh filename="../assemblies/left_leg_active/meshes/left_calf_link_visual.stl"/>
      </geometry>
      <material name="left_calf_link_material">
        <color rgba="0.61568627450980395466 0.81176470588235294379 0.92941176470588238168 1.0"/>
      </material>
    </visual>
    <inertial>
      <origin xyz="-0.0043450054391248786947 0.040752982165250771496 0.0087116093515534967495" rpy="0 0 0"/>
      <mass value="0.030999999999999992839"/>
      <inertia ixx="3.3069388685112569883e-05" ixy="-1.3783307153201298896e-06" ixz="-1.2742534026334006212e-07" iyy="7.7316525337315854217e-06" iyz="-7.335650059386048945e-08" izz="2.8031377753987751284e-05"/>
    </inertial>
  </link>
  <link name="left_ank_pitch_link">
    <visual>
      <origin xyz="0 0 0" rpy="0 -0 0"/>
      <geometry>
        <mesh filename="../assemblies/left_leg_active/meshes/left_ank_pitch_link_visual.stl"/>
      </geometry>
      <material name="left_ank_pitch_link_material">
        <color rgba="0.70321688500203349825 0.64514870846184457776 0.40484735422826251261 1.0"/>
      </material>
    </visual>
    <collision name="left_ank_pitch_link_collision">
      <origin xyz="0.01934999879449606 0.012000000104308128 0.016799999633803964" rpy="0 0 0"/>
      <geometry>
        <box size="0.084799999371171 0.04650000110268593 0.04239999828860164"/>
      </geometry>
    </collision>
    <inertial>
      <origin xyz="0.017770241891401236667 0.012301334508572112081 0.018813528244421784397" rpy="0 0 0"/>
      <mass value="0.1767637669506791076"/>
      <inertia ixx="4.7283316680251528594e-05" ixy="-1.3380598598440066277e-06" ixz="-5.5304058905152607314e-07" iyy="0.00010706456048089248178" iyz="-5.3225137839470791761e-08" izz="0.00012185522397136386665"/>
    </inertial>
  </link>
  <link name="ank_roll_link">
    <visual>
      <origin xyz="0 0 0" rpy="0 -0 0"/>
      <geometry>
        <mesh filename="../assemblies/left_leg_active/meshes/left_ank_roll_link_visual.stl"/>
      </geometry>
      <material name="ank_roll_link_material">
        <color rgba="0.61568627450980384364 0.81176470588235283277 0.92941176470588227065 1.0"/>
      </material>
    </visual>
    <collision name="ank_roll_link_collision">
      <origin xyz="-0.014500000514090061 0.0 0.038999998942017555" rpy="0 0 0"/>
      <geometry>
        <box size="0.04900000058114529 0.041999999433755875 0.12000000104308128"/>
      </geometry>
    </collision>
    <inertial>
      <origin xyz="-0.027003066516822049614 -2.0057346566329234726e-12 0.033764011359896449471" rpy="0 0 0"/>
      <mass value="0.042600000000000012856"/>
      <inertia ixx="3.7284397827464321284e-05" ixy="-5.5171856782523619006e-16" ixz="2.3929183768080488394e-06" iyy="3.7589276943350537956e-05" iyz="5.0934855332653714243e-12" izz="1.0090430906786831852e-05"/>
    </inertial>
  </link>
  <joint name="left_ank_roll" type="revolute">
    <origin xyz="0.022749999999985538734 -7.882583474838611437e-15 0.01900000000000061362" rpy="-1.5707963267949487385 -4.2119656378063955504e-14 1.5707963267951472464"/>
    <parent link="left_ank_pitch_link"/>
    <child link="ank_roll_link"/>
    <axis xyz="0 0 1"/>
    <limit effort="1" velocity="20" lower="-1.570796326794896558" upper="1.570796326794896558"/>
    <joint_properties friction="0.0"/>
  </joint>
  <joint name="left_ank_pitch" type="revolute">
    <origin xyz="-1.9512606733250257952e-15 0.10000000000000036637 0.02775000000000000383" rpy="-3.141592653589793116 3.5087959447744686916e-16 2.3008038058414658775e-14"/>
    <parent link="left_calf_link"/>
    <child link="left_ank_pitch_link"/>
    <axis xyz="0 0 1"/>
    <limit effort="1" velocity="20" lower="-1.7453292519943295336" upper="0.785398163397448279"/>
    <joint_properties friction="0.0"/>
  </joint>
  <joint name="left_knee" type="revolute">
    <origin xyz="-2.8613480456167939715e-17 -0.0087499999999999158312 0.085949999999999998623" rpy="1.57079632679489678 3.591571484825329779e-14 3.141592653589793116"/>
    <parent link="left_hip_pitch_link"/>
    <child link="left_calf_link"/>
    <axis xyz="0 0 1"/>
    <limit effort="1" velocity="20" lower="-2.0943951023931952626" upper="0"/>
    <joint_properties friction="0.0"/>
  </joint>
  <link name="xm430_plate">
    <visual>
      <origin xyz="0 0 0" rpy="0 -0 0"/>
      <geometry>
        <mesh filename="../assemblies/left_leg_active/meshes/left_xm430_plate_visual.stl"/>
      </geometry>
      <material name="xm430_plate_material">
        <color rgba="0.61568627450980395466 0.81176470588235294379 0.92941176470588227065 1.0"/>
      </material>
    </visual>
    <inertial>
      <origin xyz="-1.2470677117592975908e-17 -2.603989803260703764e-18 0.0025278513919583817798" rpy="0 0 0"/>
      <mass value="0.0026999999999999997093"/>
      <inertia ixx="1.2887178787151824688e-07" ixy="5.8739562556303580066e-08" ixz="1.3747001931663957437e-36" iyy="2.4635091298412528789e-07" iyz="1.2591564783620003869e-36" izz="3.6467998413810316538e-07"/>
    </inertial>
  </link>
  <joint name="left_knee_act" type="fixed">
    <origin xyz="2.549465851207057319e-18 0.012450000000000006201 0.044499999999999990952" rpy="-1.570796326794896558 1.570796326794896558 0"/>
    <parent link="left_hip_pitch_link"/>
    <child link="xm430_plate"/>
    <axis xyz="0 0 1"/>
    <limit effort="1" velocity="20"/>
    <joint_properties friction="0.0"/>
  </joint>
  <joint name="left_hip_yaw" type="revolute">
    <origin xyz="3.3476830706536645795e-18 3.4694469519536141888e-18 -0.0049999999999999905631" rpy="-3.141592653589793116 -9.9920072216846031328e-16 -6.2516448472107216595e-14"/>
    <parent link="spur_gear_21_teeth"/>
    <child link="left_hip_pitch_link"/>
    <axis xyz="0 0 1"/>
    <limit effort="1" velocity="20" lower="-1.570796326794896558" upper="1.570796326794896558"/>
    <joint_properties friction="0.0"/>
  </joint>
  <joint name="left_hip_yaw_fixed" type="fixed">
    <origin xyz="0 -0.028000000000000004052 -0.018999999999999999528" rpy="-1.5707963267948932273 1.5707963267948956698 0"/>
    <parent link="hip_yaw_link"/>
    <child link="spur_gear_21_teeth"/>
    <axis xyz="0 0 1"/>
    <limit effort="1" velocity="20"/>
    <joint_properties friction="0.0"/>
  </joint>
  <joint name="left_hip_roll" type="revolute">
    <origin xyz="-0.024000000716139682777 0.019000000152448071056 0.019000000152447796969" rpy="-1.57079632679489678 -1.5707963267948943376 0"/>
    <parent link="2xc430"/>
    <child link="hip_yaw_link"/>
    <axis xyz="0 0 1"/>
    <limit effort="1" velocity="20" lower="-0.785398163397448279" upper="0.785398163397448279"/>
    <joint_properties friction="0.0"/>
  </joint>
  <link name="2xc430_2">
    <visual>
      <origin xyz="0 0 0" rpy="0 -0 0"/>
      <geometry>
        <mesh filename="../assemblies/right_leg_active/meshes/right_2xc430_visual.stl"/>
      </geometry>
      <material name="2xc430_material">
        <color rgba="0.51698661238356047321 0.50347815951093488618 0.49050589017722012741 1.0"/>
      </material>
    </visual>
    <inertial>
      <origin xyz="-0.0120001511339564923 0.00049588831385626367092 0.01850401924450319896" rpy="0 0 0"/>
      <mass value="0.11059999999836234164"/>
      <inertia ixx="2.2818802599017385101e-05" ixy="4.6888548258345894655e-08" ixz="4.6520143289217505514e-08" iyy="3.0871666424467696587e-05" iyz="-5.7477343899723834052e-07" izz="3.0871632082336744173e-05"/>
    </inertial>
  </link>
  <link name="hip_yaw_link_2">
    <visual>
      <origin xyz="0 0 0" rpy="0 -0 0"/>
      <geometry>
        <mesh filename="../assemblies/right_leg_active/meshes/right_hip_yaw_link_visual.stl"/>
      </geometry>
      <material name="hip_yaw_link_material">
        <color rgba="0.61568627450980395466 0.81176470588235294379 0.92941176470588238168 1.0"/>
      </material>
    </visual>
    <inertial>
      <origin xyz="-2.678882801192081122e-18 -0.015800610849654277146 -0.019005670096647754586" rpy="0 0 0"/>
      <mass value="0.013199999999999992989"/>
      <inertia ixx="5.789461597517412337e-06" ixy="-1.9489251097466773533e-36" ixz="3.4468362863536094383e-36" iyy="5.0110144042848776317e-06" iyz="1.1826010760651176287e-09" izz="2.7344876354814331659e-06"/>
    </inertial>
  </link>
  <link name="spur_gear_21_teeth_2">
    <visual>
      <origin xyz="0 0 0" rpy="0 -0 0"/>
      <geometry>
        <mesh filename="../assemblies/right_leg_active/meshes/right_spur_gear_21_teeth_visual.stl"/>
      </geometry>
      <material name="spur_gear_21_teeth_material">
        <color rgba="0.61568627450980395466 0.81176470588235294379 0.9294117647058824927 1.0"/>
      </material>
    </visual>
    <inertial>
      <origin xyz="-4.550528933541158048e-11 -1.6782163661890817574e-11 -0.00249241020062506086" rpy="0 0 0"/>
      <mass value="0.0022000000000000001325"/>
      <inertia ixx="7.0162310059594196881e-08" ixy="0" ixz="4.8298814937805552291e-38" iyy="7.016231005804746178e-08" iyz="0" izz="1.3125544198538289306e-07"/>
    </inertial>
  </link>
  <link name="right_hip_pitch_link">
    <visual>
      <origin xyz="0 0 0" rpy="0 -0 0"/>
      <geometry>
        <mesh filename="../assemblies/right_leg_active/meshes/right_hip_pitch_link_visual.stl"/>
      </geometry>
      <material name="right_hip_pitch_link_material">
        <color rgba="0.81231119922470307326 0.7131158892107314351 0.33680089849959421455 1.0"/>
      </material>
    </visual>
    <collision name="right_hip_pitch_link_collision">
      <origin xyz="0.009275000542402267 -0.004349999129772186 0.05247500166296959" rpy="0 0 0"/>
      <geometry>
        <box size="0.05855000019073486 0.042399998754262924 0.10495000332593918"/>
      </geometry>
    </collision>
    <inertial>
      <origin xyz="0.010187905578010464716 -0.005618846722851051842 0.038815928333491969693" rpy="0 0 0"/>
      <mass value="0.14548965119785964295"/>
      <inertia ixx="7.094204959486600094e-05" ixy="1.1158758975154224099e-06" ixz="7.6515558781279078741e-06" iyy="8.5157398802913609982e-05" iyz="1.06993373990861437e-06" izz="4.094530693523142404e-05"/>
    </inertial>
  </link>
  <link name="spur_gear_18_teeth_2">
    <visual>
      <origin xyz="0 0 0" rpy="0 -0 0"/>
      <geometry>
        <mesh filename="../assemblies/right_leg_active/meshes/right_spur_gear_18_teeth_visual.stl"/>
      </geometry>
      <material name="spur_gear_18_teeth_material">
        <color rgba="0.61568627450980395466 0.81176470588235294379 0.92941176470588238168 1.0"/>
      </material>
    </visual>
    <inertial>
      <origin xyz="-1.2350917852414122165e-14 -3.7635296765399104409e-13 0.0017500000000010135486" rpy="0 0 0"/>
      <mass value="0.0011999999999999998949"/>
      <inertia ixx="2.936789981067607588e-08" ixy="-5.2777750224259310609e-37" ixz="2.2363428465405589407e-37" iyy="2.9367899814783318789e-08" iyz="-3.5199528326541291339e-38" izz="5.6306346207859581581e-08"/>
    </inertial>
  </link>
  <joint name="right_hip_yaw_drive" type="fixed">
    <origin xyz="0.01919999999999898524 0.00019999999999894754743 -3.8975767058246901797e-14" rpy="-3.1415926535897891192 -2.5796031977166208939e-13 5.3427523162437313535e-13"/>
    <parent link="right_hip_pitch_link"/>
    <child link="spur_gear_18_teeth_2"/>
    <axis xyz="0 0 1"/>
    <limit effort="1" velocity="20"/>
    <joint_properties friction="0.0"/>
  </joint>
  <link name="right_calf_link">
    <visual>
      <origin xyz="0 0 0" rpy="0 -0 0"/>
      <geometry>
        <mesh filename="../assemblies/right_leg_active/meshes/right_calf_link_visual.stl"/>
      </geometry>
      <material name="right_calf_link_material">
        <color rgba="0.61568627450980395466 0.81176470588235294379 0.92941176470588238168 1.0"/>
      </material>
    </visual>
    <inertial>
      <origin xyz="-0.0043450054394401152469 -0.040752982164757575734 0.0087116093514751913318" rpy="0 0 0"/>
      <mass value="0.030999999999999992839"/>
      <inertia ixx="3.3069388685437213894e-05" ixy="1.3783307152005711891e-06" ixz="-1.2742534017149146215e-07" iyy="7.7316525337491173096e-06" iyz="7.3356500737974886855e-08" izz="2.8031377754212021892e-05"/>
    </inertial>
  </link>
  <link name="right_ank_pitch_link">
    <visual>
      <origin xyz="0 0 0" rpy="0 -0 0"/>
      <geometry>
        <mesh filename="../assemblies/right_leg_active/meshes/right_ank_pitch_link_visual.stl"/>
      </geometry>
      <material name="right_ank_pitch_link_material">
        <color rgba="0.70321688500203349825 0.64514870846184457776 0.40484735422826251261 1.0"/>
      </material>
    </visual>
    <collision name="right_ank_pitch_link_collision">
      <origin xyz="-0.01934999879449606 0.012000001966953278 0.016799999633803964" rpy="0 0 0"/>
      <geometry>
        <box size="0.084799999371171 0.04650000482797623 0.04239999828860164"/>
      </geometry>
    </collision>
    <inertial>
      <origin xyz="-0.017770241889542692099 0.012301334508572231777 0.018814514831173610038" rpy="0 0 0"/>
      <mass value="0.1767637669506791076"/>
      <inertia ixx="4.7283381546857870814e-05" ixy="1.33805982072425138e-06" ixz="6.15326286073951289e-07" iyy="0.00010706462535917242202" iyz="-5.1080086246298360137e-08" izz="0.00012185522398303844723"/>
    </inertial>
  </link>
  <link name="ank_roll_link_2">
    <visual>
      <origin xyz="0 0 0" rpy="0 -0 0"/>
      <geometry>
        <mesh filename="../assemblies/right_leg_active/meshes/right_ank_roll_link_visual.stl"/>
      </geometry>
      <material name="ank_roll_link_material">
        <color rgba="0.61568627450980384364 0.81176470588235283277 0.92941176470588227065 1.0"/>
      </material>
    </visual>
    <collision name="ank_roll_link_2_collision">
      <origin xyz="-0.014500000514090061 0.0 0.038999998942017555" rpy="0 0 0"/>
      <geometry>
        <box size="0.04900000058114529 0.041999999433755875 0.12000000104308128"/>
      </geometry>
    </collision>
    <inertial>
      <origin xyz="-0.027003066516822035736 -2.0057347814959544714e-12 0.033764011359896435593" rpy="0 0 0"/>
      <mass value="0.042600000000000012856"/>
      <inertia ixx="3.7284397827464402599e-05" ixy="-5.5174204219832163841e-16" ixz="2.392918376808064933e-06" iyy="3.7589276943350354997e-05" iyz="5.0934855163573012951e-12" izz="1.009043090678676409e-05"/>
    </inertial>
  </link>
  <joint name="right_ank_roll" type="revolute">
    <origin xyz="-0.022749999999990215549 -4.1078251911130791996e-15 0.018999999999999885036" rpy="1.5707963267947835373 9.1691796370025759616e-15 1.5707963267947813168"/>
    <parent link="right_ank_pitch_link"/>
    <child link="ank_roll_link_2"/>
    <axis xyz="0 0 1"/>
    <limit effort="1" velocity="20" lower="-1.570796326794896558" upper="1.570796326794896558"/>
    <joint_properties friction="0.0"/>
  </joint>
  <joint name="right_ank_pitch" type="revolute">
    <origin xyz="5.6180870362790719763e-17 -0.10000000000000083822 0.027749999999999996891" rpy="-3.1415926535897908956 2.0683074016305722883e-15 3.1415926535897571448"/>
    <parent link="right_calf_link"/>
    <child link="right_ank_pitch_link"/>
    <axis xyz="0 0 1"/>
    <limit effort="1" velocity="20" lower="-0.785398163397448279" upper="1.7453292519943295336"/>
    <joint_properties friction="0.0"/>
  </joint>
  <joint name="right_knee" type="revolute">
    <origin xyz="4.7284234669871609276e-16 -0.0087500000000002471634 0.085950000000000914557" rpy="-1.5707963267948237274 -8.4836630014116765856e-15 2.2217821261973663682e-14"/>
    <parent link="right_hip_pitch_link"/>
    <child link="right_calf_link"/>
    <axis xyz="0 0 1"/>
    <limit effort="1" velocity="20" lower="0" upper="2.0943951023931952626"/>
    <joint_properties friction="0.0"/>
  </joint>
  <link name="xm430_plate_2">
    <visual>
      <origin xyz="0 0 0" rpy="0 -0 0"/>
      <geometry>
        <mesh filename="../assemblies/right_leg_active/meshes/right_xm430_plate_visual.stl"/>
      </geometry>
      <material name="xm430_plate_material">
        <color rgba="0.61568627450980395466 0.81176470588235294379 0.92941176470588227065 1.0"/>
      </material>
    </visual>
    <inertial>
      <origin xyz="-9.7261306791801168226e-19 -1.6840355871754458999e-17 0.0025278513919583817798" rpy="0 0 0"/>
      <mass value="0.0026999999999999997093"/>
      <inertia ixx="2.4635091298412534083e-07" ixy="5.8739562556303546978e-08" ixz="0" iyy="1.2887178787151819394e-07" iyz="0" izz="3.6467998413810316538e-07"/>
    </inertial>
  </link>
  <joint name="right_knee_act" type="fixed">
    <origin xyz="-3.6752903668471980207e-16 0.012449999999999988853 0.044500000000000546063" rpy="-1.570796326794896558 2.9976021664670273115e-15 -2.7630262808068215764e-25"/>
    <parent link="right_hip_pitch_link"/>
    <child link="xm430_plate_2"/>
    <axis xyz="0 0 1"/>
    <limit effort="1" velocity="20"/>
    <joint_properties friction="0.0"/>
  </joint>
  <joint name="right_hip_yaw" type="revolute">
    <origin xyz="4.4219386519237269229e-16 2.0122792321330962295e-16 -0.0050000000000000044409" rpy="3.141592653589793116 -1.1102230246227232743e-16 7.4562918480963285736e-14"/>
    <parent link="spur_gear_21_teeth_2"/>
    <child link="right_hip_pitch_link"/>
    <axis xyz="0 0 1"/>
    <limit effort="1" velocity="20" lower="-1.570796326794896558" upper="1.570796326794896558"/>
    <joint_properties friction="0.0"/>
  </joint>
  <joint name="right_hip_yaw_fixed" type="fixed">
    <origin xyz="-3.4694469519536141888e-18 -0.027999999999999997113 -0.019000000000000002998" rpy="-1.5707963267949067721 1.5707963267948852337 0"/>
    <parent link="hip_yaw_link_2"/>
    <child link="spur_gear_21_teeth_2"/>
    <axis xyz="0 0 1"/>
    <limit effort="1" velocity="20"/>
    <joint_properties friction="0.0"/>
  </joint>
  <joint name="right_hip_roll" type="revolute">
    <origin xyz="-0.024000000716139776452 0.019000000152447758806 0.019000000152447581864" rpy="-1.5707963267949041075 -1.5707963267948830133 0"/>
    <parent link="2xc430_2"/>
    <child link="hip_yaw_link_2"/>
    <axis xyz="0 0 1"/>
    <limit effort="1" velocity="20" lower="-0.785398163397448279" upper="0.785398163397448279"/>
    <joint_properties friction="0.0"/>
  </joint>
  <link name="sho_pitch_link">
    <visual>
      <origin xyz="0 0 0" rpy="0 -0 0"/>
      <geometry>
        <mesh filename="../assemblies/left_arm_active/meshes/left_sho_pitch_link_visual.stl"/>
      </geometry>
      <material name="sho_pitch_link_material">
        <color rgba="0.61568627450980395466 0.81176470588235294379 0.92941176470588227065 1.0"/>
      </material>
    </visual>
    <inertial>
      <origin xyz="-1.025903438159899119e-18 -2.1966078074444220184e-18 0.012913250798677602602" rpy="0 0 0"/>
      <mass value="0.0085999999999999982708"/>
      <inertia ixx="1.8365636406635814379e-06" ixy="0" ixz="0" iyy="4.0110869076839152165e-06" iyz="0" izz="3.5160516450492493809e-06"/>
    </inertial>
  </link>
  <link name="2xl430_gears">
    <visual>
      <origin xyz="0 0 0" rpy="0 -0 0"/>
      <geometry>
        <mesh filename="../assemblies/left_arm_active/meshes/left_2xl430_gears_visual.stl"/>
      </geometry>
      <material name="2xl430_gears_material">
        <color rgba="0.75914767920569214965 0.85560384745670925444 0.90519468321360607721 1.0"/>
      </material>
    </visual>
    <collision name="2xl430_gears_collision">
      <origin xyz="-0.011708511453562323 -0.002663695648909629 -0.019869671274007777" rpy="0 0 0"/>
      <geometry>
        <sphere radius="0.031174628050040995"/>
      </geometry>
    </collision>
    <inertial>
      <origin xyz="-0.011592905737981719708 -0.0024238553642539654651 -0.018551095523800652243" rpy="0 0 0"/>
      <mass value="0.11800003674524911501"/>
      <inertia ixx="2.7511021050425137297e-05" ixy="9.0043904315059743301e-07" ixz="-2.3349710123436745739e-08" iyy="3.2796197843345773501e-05" iyz="-6.5715119654595532665e-07" izz="3.577573983574187309e-05"/>
    </inertial>
  </link>
  <link name="spur_1m_24t_drive">
    <visual>
      <origin xyz="0 0 0" rpy="0 -0 0"/>
      <geometry>
        <mesh filename="../assemblies/left_arm_active/meshes/left_spur_1m_24t_drive_visual.stl"/>
      </geometry>
      <material name="spur_1m_24t_drive_material">
        <color rgba="0.61568627450980395466 0.81176470588235294379 0.92941176470588238168 1.0"/>
      </material>
    </visual>
    <inertial>
      <origin xyz="3.0326032611483892113e-15 -3.3912620811388928147e-16 0.0048096451474093108655" rpy="0 0 0"/>
      <mass value="0.0031999999999999997197"/>
      <inertia ixx="1.409759888701696132e-07" ixy="1.5562823114660456276e-15" ixz="-2.008449854153761406e-29" iyy="1.4097598803635996198e-07" iyz="1.6394294515261297612e-30" izz="2.4107776386988835496e-07"/>
    </inertial>
  </link>
  <joint name="left_sho_yaw_drive" type="fixed">
    <origin xyz="-0.024000000716141011575 -0.019000000152450600283 -0.019000000152443286688" rpy="1.5707963267948328312 -1.2315316060159674745e-15 7.63621479414374471e-14"/>
    <parent link="2xl430_gears"/>
    <child link="spur_1m_24t_drive"/>
    <axis xyz="0 0 1"/>
    <limit effort="1" velocity="20"/>
    <joint_properties friction="0.0"/>
  </joint>
  <link name="spur_1m_24t_driven">
    <visual>
      <origin xyz="0 0 0" rpy="0 -0 0"/>
      <geometry>
        <mesh filename="../assemblies/left_arm_active/meshes/left_spur_1m_24t_driven_visual.stl"/>
      </geometry>
      <material name="spur_1m_24t_driven_material">
        <color rgba="0.23137254901960788156 0.38039215686274502337 0.7058823529411765163 1.0"/>
      </material>
    </visual>
    <inertial>
      <origin xyz="-6.1597507571280238057e-18 -1.688384205958136519e-15 -0.00097237500038395777158" rpy="0 0 0"/>
      <mass value="0.0026999999999999997093"/>
      <inertia ixx="1.2202334915684085792e-07" ixy="2.7523294133209990513e-36" ixz="-7.3269571490458995975e-30" iyy="1.2202334915684064616e-07" iyz="2.3906142240509615961e-38" izz="2.3180293204341252239e-07"/>
    </inertial>
  </link>
  <link name="sho_yaw_link">
    <visual>
      <origin xyz="0 0 0" rpy="0 -0 0"/>
      <geometry>
        <mesh filename="../assemblies/left_arm_active/meshes/left_sho_yaw_link_visual.stl"/>
      </geometry>
      <material name="sho_yaw_link_material">
        <color rgba="0.61568627450980395466 0.81176470588235294379 0.92941176470588238168 1.0"/>
      </material>
    </visual>
    <inertial>
      <origin xyz="-1.3035750898319770195e-18 2.6069328434161451193e-18 -0.024649285094360082193" rpy="0 0 0"/>
      <mass value="0.014500000000000007674"/>
      <inertia ixx="9.2365904614004473434e-06" ixy="3.5862833440690462015e-13" ixz="9.1428418910883641815e-28" iyy="5.8163826335078791714e-06" iyz="3.2690928711022967479e-35" izz="4.5074356741562122031e-06"/>
    </inertial>
  </link>
  <link name="2xl430_gears_2">
    <visual>
      <origin xyz="0 0 0" rpy="0 -0 0"/>
      <geometry>
        <mesh filename="../assemblies/left_arm_active/meshes/left_2xl430_gears_2_visual.stl"/>
      </geometry>
      <material name="2xl430_gears_2_material">
        <color rgba="0.75914767920569214965 0.85560384745670925444 0.90519468321360607721 1.0"/>
      </material>
    </visual>
    <collision name="2xl430_gears_2_collision">
      <origin xyz="-0.011709013494106524 -0.0026637945762991427 -0.019868450994299965" rpy="0 0 0"/>
      <geometry>
        <sphere radius="0.031173800831198285"/>
      </geometry>
    </collision>
    <inertial>
      <origin xyz="-0.011592905737977830458 -0.0024238553642531319304 -0.018551095523810002402" rpy="0 0 0"/>
      <mass value="0.11800003674524911501"/>
      <inertia ixx="2.7511021050425449005e-05" ixy="9.0043904315422929852e-07" ixz="-2.3349710124855247993e-08" iyy="3.2796197843347501448e-05" iyz="-6.5715119654968301277e-07" izz="3.577573983574221868e-05"/>
    </inertial>
  </link>
  <link name="spur_1m_24t_drive_2">
    <visual>
      <origin xyz="0 0 0" rpy="0 -0 0"/>
      <geometry>
        <mesh filename="../assemblies/left_arm_active/meshes/left_spur_1m_24t_drive_2_visual.stl"/>
      </geometry>
      <material name="spur_1m_24t_drive_2_material">
        <color rgba="0.61568627450980395466 0.81176470588235294379 0.92941176470588238168 1.0"/>
      </material>
    </visual>
    <inertial>
      <origin xyz="3.0326032635612721456e-15 -3.3912620813973872492e-16 0.0048096451474093134676" rpy="0 0 0"/>
      <mass value="0.0031999999999999997197"/>
      <inertia ixx="1.4097598887016953379e-07" ixy="1.5562823114943523235e-15" ixz="-4.6297932308656121067e-28" iyy="1.4097598803635996198e-07" iyz="2.2330386657934582872e-29" izz="2.4107776386988835496e-07"/>
    </inertial>
  </link>
  <joint name="left_elbow_yaw_drive" type="fixed">
    <origin xyz="-0.024000000716137552537 -0.019000000152447502066 -0.019000000152459547986" rpy="1.5707963267950562081 -2.470655165606289817e-13 -1.8325179468455831644e-13"/>
    <parent link="2xl430_gears_2"/>
    <child link="spur_1m_24t_drive_2"/>
    <axis xyz="0 0 1"/>
    <limit effort="1" velocity="20"/>
    <joint_properties friction="0.0"/>
  </joint>
  <link name="spur_1m_24t_driven_2">
    <visual>
      <origin xyz="0 0 0" rpy="0 -0 0"/>
      <geometry>
        <mesh filename="../assemblies/left_arm_active/meshes/left_spur_1m_24t_driven_2_visual.stl"/>
      </geometry>
      <material name="spur_1m_24t_driven_2_material">
        <color rgba="0.23137254901960788156 0.38039215686274502337 0.7058823529411765163 1.0"/>
      </material>
    </visual>
    <inertial>
      <origin xyz="-2.6919984763826045554e-18 -1.6851535667301797593e-15 -0.00097237500038395083268" rpy="0 0 0"/>
      <mass value="0.0026999999999999997093"/>
      <inertia ixx="1.2202334915684080498e-07" ixy="-1.4158378337979601932e-26" ixz="-1.6652141981526740106e-31" iyy="1.2202334915684064616e-07" iyz="-6.1216890803012590929e-29" izz="2.3180293204341252239e-07"/>
    </inertial>
  </link>
  <link name="elb_yaw_link">
    <visual>
      <origin xyz="0 0 0" rpy="0 -0 0"/>
      <geometry>
        <mesh filename="../assemblies/left_arm_active/meshes/left_elb_yaw_link_visual.stl"/>
      </geometry>
      <material name="elb_yaw_link_material">
        <color rgba="0.61568627450980395466 0.81176470588235294379 0.92941176470588227065 1.0"/>
      </material>
    </visual>
    <inertial>
      <origin xyz="5.3127688027775035015e-08 0.0019833638641961613865 -0.023416643551549952418" rpy="0 0 0"/>
      <mass value="0.017500000000000005135"/>
      <inertia ixx="1.4134344903109199776e-05" ixy="1.6945783922010719072e-12" ixz="-1.1286398721833085835e-11" iyy="6.6435900776211340404e-06" iyz="1.0545227077253051227e-06" izz="8.9925290757998993713e-06"/>
    </inertial>
  </link>
  <link name="spur_1m_24t_driven_3">
    <visual>
      <origin xyz="0 0 0" rpy="0 -0 0"/>
      <geometry>
        <mesh filename="../assemblies/left_arm_active/meshes/left_spur_1m_24t_driven_3_visual.stl"/>
      </geometry>
      <material name="spur_1m_24t_driven_3_material">
        <color rgba="0.23137254901960788156 0.38039215686274502337 0.7058823529411765163 1.0"/>
      </material>
    </visual>
    <inertial>
      <origin xyz="-2.6903273536523174272e-18 -1.6883828105019308173e-15 -0.0025723750003839550293" rpy="0 0 0"/>
      <mass value="0.0026999999999999997093"/>
      <inertia ixx="1.2202334915684080498e-07" ixy="-6.8849887603967411276e-32" ixz="-2.6410010759070278003e-28" iyy="1.2202334915684059322e-07" iyz="2.0286938869726816775e-26" izz="2.3180293204341252239e-07"/>
    </inertial>
  </link>
  <link name="2xl430_gears_3">
    <visual>
      <origin xyz="0 0 0" rpy="0 -0 0"/>
      <geometry>
        <mesh filename="../assemblies/left_arm_active/meshes/left_2xl430_gears_3_visual.stl"/>
      </geometry>
      <material name="2xl430_gears_3_material">
        <color rgba="0.75914767920569214965 0.85560384745670925444 0.90519468321360607721 1.0"/>
      </material>
    </visual>
    <collision name="2xl430_gears_3_collision">
      <origin xyz="-0.0008536254376339718 0.01171871446801604 -0.024337078544579498" rpy="0 0 0"/>
      <geometry>
        <sphere radius="0.031160574725534962"/>
      </geometry>
    </collision>
    <inertial>
      <origin xyz="0.00044890447620203518522 0.011592905379898215887 -0.024576144788197726992" rpy="0 0 0"/>
      <mass value="0.11800003674524911501"/>
      <inertia ixx="3.5775739835741527501e-05" ixy="2.3349710123577267181e-08" ixz="6.571511965489162362e-07" iyy="2.7511021050426404458e-05" iyz="9.0043904315389906155e-07" izz="3.2796197843345726067e-05"/>
    </inertial>
  </link>
  <link name="spur_1m_24t_drive_3">
    <visual>
      <origin xyz="0 0 0" rpy="0 -0 0"/>
      <geometry>
        <mesh filename="../assemblies/left_arm_active/meshes/left_spur_1m_24t_drive_3_visual.stl"/>
      </geometry>
      <material name="spur_1m_24t_drive_3_material">
        <color rgba="0.61568627450980395466 0.81176470588235294379 0.92941176470588238168 1.0"/>
      </material>
    </visual>
    <inertial>
      <origin xyz="3.060358827889013058e-15 -3.4111303900242703925e-16 0.0048096451474093065287" rpy="0 0 0"/>
      <mass value="0.0031999999999999997197"/>
      <inertia ixx="1.4097598887016953379e-07" ixy="1.5562823135089737022e-15" ixz="-1.1512514101231046835e-27" iyy="1.4097598803635998845e-07" iyz="2.2291261639049831572e-27" izz="2.4107776386988835496e-07"/>
    </inertial>
  </link>
  <joint name="left_wrist_pitch_drive" type="fixed">
    <origin xyz="-1.524411534503666843e-10 0.024000000358058687366 -0.0080000000000068870187" rpy="9.3688325669630329923e-15 -2.4754144734777612982e-13 -1.570796326794971387"/>
    <parent link="2xl430_gears_3"/>
    <child link="spur_1m_24t_drive_3"/>
    <axis xyz="0 0 1"/>
    <limit effort="1" velocity="20"/>
    <joint_properties friction="0.0"/>
  </joint>
  <link name="hand">
    <visual>
      <origin xyz="0 0 0" rpy="0 -0 0"/>
      <geometry>
        <mesh filename="../assemblies/left_arm_active/meshes/left_hand_visual.stl"/>
      </geometry>
      <material name="hand_material">
        <color rgba="0.6414991312980887761 0.67624720774385704836 0.69709605361131787848 1.0"/>
      </material>
    </visual>
    <collision name="hand_collision">
      <origin xyz="-0.0044999998062849045 0.023250000085681677 -0.019000000320374966" rpy="0 0 0"/>
      <geometry>
        <box size="0.05000000074505806 0.06749999988824129 0.07400000281631947"/>
      </geometry>
    </collision>
    <inertial>
      <origin xyz="-0.0037132560743682236672 0.042135580180293723263 -0.019513129422372363364" rpy="0 0 0"/>
      <mass value="0.039500000000000000389"/>
      <inertia ixx="2.4655505305536037772e-05" ixy="6.2292690516536515991e-07" ixz="-1.3905202790257463006e-08" iyy="2.5499495709674586328e-05" iyz="4.0482284361505544926e-08" izz="1.3476712281039084689e-05"/>
    </inertial>
  </link>
  <joint name="left_wrist_roll" type="revolute">
    <origin xyz="0.019000000000007864764 -3.580815921555569048e-10 -0.027000000152448074692" rpy="-3.141592653589793116 -1.5707963267945825869 0"/>
    <parent link="2xl430_gears_3"/>
    <child link="hand"/>
    <axis xyz="0 0 1"/>
    <limit effort="1" velocity="20" lower="-1.9198621771937625091" upper="1.3962634015954635824"/>
    <joint_properties friction="0.0"/>
  </joint>
  <link name="wrist_bearing_plate">
    <visual>
      <origin xyz="0 0 0" rpy="0 -0 0"/>
      <geometry>
        <mesh filename="../assemblies/left_arm_active/meshes/left_wrist_bearing_plate_visual.stl"/>
      </geometry>
      <material name="wrist_bearing_plate_material">
        <color rgba="0.71932243125689054875 0.63128434304969727187 0.52422389360984933404 1.0"/>
      </material>
    </visual>
    <inertial>
      <origin xyz="-0.007583558312149987074 -0.015499999999999972133 -0.0018386323705903283732" rpy="0 0 0"/>
      <mass value="0.0049000367468305557062"/>
      <inertia ixx="4.9707430109150107956e-07" ixy="5.8442651625198521782e-23" ixz="1.8100904820814022013e-08" iyy="7.1268523603538521295e-07" iyz="1.0938305468180491225e-23" izz="1.1919657811600107117e-06"/>
    </inertial>
  </link>
  <joint name="left_wrist_pitch_fixed" type="fixed">
    <origin xyz="0.015500000000007483486 -1.7374990335383699858e-14 -0.044999999999998908928" rpy="4.0578672398099256913e-14 -2.8213543071750907979e-13 -1.570796326794906328"/>
    <parent link="2xl430_gears_3"/>
    <child link="wrist_bearing_plate"/>
    <axis xyz="0 0 1"/>
    <limit effort="1" velocity="20"/>
    <joint_properties friction="0.0"/>
  </joint>
  <joint name="left_wrist_pitch" type="revolute">
    <origin xyz="0 -1.3383120566617945357e-18 -0.0015999999999999961735" rpy="-2.8942931320395828399e-14 -2.5018666387969439484e-14 -1.5029360097675703578"/>
    <parent link="spur_1m_24t_driven_3"/>
    <child link="2xl430_gears_3"/>
    <axis xyz="0 0 1"/>
    <limit effort="1" velocity="20" lower="-1.3962634015954635824" upper="1.9198621771937625091"/>
    <joint_properties friction="0.0"/>
  </joint>
  <joint name="left_wrist_roll_fixed" type="fixed">
    <origin xyz="-1.6940658945086006781e-21 -0.025299999999999999573 -0.052000000000000032307" rpy="1.5707963267949238695 -1.5707963267948696906 0"/>
    <parent link="elb_yaw_link"/>
    <child link="spur_1m_24t_driven_3"/>
    <axis xyz="0 0 1"/>
    <limit effort="1" velocity="20"/>
    <joint_properties friction="0.0"/>
  </joint>
  <joint name="left_elbow_yaw_fixed" type="fixed">
    <origin xyz="0 3.4694469519536141888e-18 0.0015999999999999903189" rpy="3.141592653589793116 1.7371588856516367895e-15 -7.1482908950121119081e-21"/>
    <parent link="spur_1m_24t_driven_2"/>
    <child link="elb_yaw_link"/>
    <axis xyz="0 0 1"/>
    <limit effort="1" velocity="20"/>
    <joint_properties friction="0.0"/>
  </joint>
  <joint name="left_elbow_yaw" type="revolute">
    <origin xyz="-3.5806394654835926872e-10 -0.027000000152452907631 -0.019000000000006612294" rpy="-1.5707963271033555941 1.5702961013580483129 3.1415926532772431301"/>
    <parent link="2xl430_gears_2"/>
    <child link="spur_1m_24t_driven_2"/>
    <axis xyz="0 0 1"/>
    <limit effort="1" velocity="20" lower="-2.6179938779914944114" upper="2.6179938779914944114"/>
    <joint_properties friction="0.0"/>
  </joint>
  <joint name="left_elbow_roll" type="revolute">
    <origin xyz="0 -0.019000000000000002998 -0.05900000000000000383" rpy="1.570796326794896558 -9.1511985033140475399e-06 9.9917328930995459489e-16"/>
    <parent link="sho_yaw_link"/>
    <child link="2xl430_gears_2"/>
    <axis xyz="0 0 1"/>
    <limit effort="1" velocity="20" lower="-1.9198621771937625091" upper="2.4434609527920612138"/>
    <joint_properties friction="0.0"/>
  </joint>
  <joint name="left_sho_yaw_fixed" type="fixed">
    <origin xyz="-6.9388939039072283776e-18 0 0.0015999999999999972577" rpy="-3.1415926535897917837 7.771562309448331808e-16 7.7715611725339221982e-16"/>
    <parent link="spur_1m_24t_driven"/>
    <child link="sho_yaw_link"/>
    <axis xyz="0 0 1"/>
    <limit effort="1" velocity="20"/>
    <joint_properties friction="0.0"/>
  </joint>
  <joint name="left_sho_yaw" type="revolute">
    <origin xyz="-3.5807029216683439188e-10 -0.027000000152450923108 -0.018999999999999881567" rpy="1.5707963267948492625 7.0146039834906763197e-14 9.489446512533569504e-14"/>
    <parent link="2xl430_gears"/>
    <child link="spur_1m_24t_driven"/>
    <axis xyz="0 0 1"/>
    <limit effort="1" velocity="20" lower="-2.6179938779914944114" upper="2.6179938779914944114"/>
    <joint_properties friction="0.0"/>
  </joint>
  <joint name="left_sho_roll" type="revolute">
    <origin xyz="-0.018999999999999999528 1.0056362270253492431e-17 0.027000000000000003164" rpy="3.141592653589793116 1.5707956970996790336 0"/>
    <parent link="sho_pitch_link"/>
    <child link="2xl430_gears"/>
    <axis xyz="0 0 1"/>
    <limit effort="1" velocity="20" lower="-1.570796326794896558" upper="0.34906585039886589561"/>
    <joint_properties friction="0.0"/>
  </joint>
  <link name="sho_pitch_link_2">
    <visual>
      <origin xyz="0 0 0" rpy="0 -0 0"/>
      <geometry>
        <mesh filename="../assemblies/right_arm_active/meshes/right_sho_pitch_link_visual.stl"/>
      </geometry>
      <material name="sho_pitch_link_material">
        <color rgba="0.61568627450980395466 0.81176470588235294379 0.92941176470588227065 1.0"/>
      </material>
    </visual>
    <inertial>
      <origin xyz="-1.025903438159899119e-18 -2.1966078074444289517e-18 0.012913250798677602602" rpy="0 0 0"/>
      <mass value="0.0085999999999999982708"/>
      <inertia ixx="1.8365636406635814379e-06" ixy="2.7052466620977967735e-97" ixz="-6.0867229013657688598e-136" iyy="4.0110869076839152165e-06" iyz="-1.6935833339184753197e-44" izz="3.5160516450492493809e-06"/>
    </inertial>
  </link>
  <link name="2xl430_gears_4">
    <visual>
      <origin xyz="0 0 0" rpy="0 -0 0"/>
      <geometry>
        <mesh filename="../assemblies/right_arm_active/meshes/right_2xl430_gears_visual.stl"/>
      </geometry>
      <material name="2xl430_gears_material">
        <color rgba="0.75914767920569214965 0.85560384745670925444 0.90519468321360607721 1.0"/>
      </material>
    </visual>
    <collision name="2xl430_gears_4_collision">
      <origin xyz="-0.01170851145356234 -0.002663695648909648 -0.019869671274007784" rpy="0 0 0"/>
      <geometry>
        <sphere radius="0.031174628050041002"/>
      </geometry>
    </collision>
    <inertial>
      <origin xyz="-0.011592905737978696085 -0.0024238553642522840843 -0.018551095523803726173" rpy="0 0 0"/>
      <mass value="0.11800003674524911501"/>
      <inertia ixx="2.7511021050424646017e-05" ixy="9.0043904315135573925e-07" ixz="-2.3349710123960218718e-08" iyy="3.2796197843346207182e-05" iyz="-6.5715119654693386146e-07" izz="3.5775739835740998952e-05"/>
    </inertial>
  </link>
  <link name="spur_1m_24t_drive_4">
    <visual>
      <origin xyz="0 0 0" rpy="0 -0 0"/>
      <geometry>
        <mesh filename="../assemblies/right_arm_active/meshes/right_spur_1m_24t_drive_visual.stl"/>
      </geometry>
      <material name="spur_1m_24t_drive_material">
        <color rgba="0.61568627450980395466 0.81176470588235294379 0.92941176470588238168 1.0"/>
      </material>
    </visual>
    <inertial>
      <origin xyz="3.0326032612408354263e-15 -3.3912620811388938008e-16 0.0048096451474093030592" rpy="0 0 0"/>
      <mass value="0.0031999999999999997197"/>
      <inertia ixx="1.4097598887016958673e-07" ixy="1.556282310200251252e-15" ixz="3.9554371954665940773e-37" iyy="1.4097598803635998845e-07" iyz="-1.3068306635892902166e-36" izz="2.4107776386988835496e-07"/>
    </inertial>
  </link>
  <joint name="right_sho_yaw_drive" type="fixed">
    <origin xyz="-0.024000000716138267243 -0.019000000152445337132 -0.019000000152448424939" rpy="1.5707963267949289765 -7.4062049324254792929e-14 1.9645226351351914911e-14"/>
    <parent link="2xl430_gears_4"/>
    <child link="spur_1m_24t_drive_4"/>
    <axis xyz="0 0 1"/>
    <limit effort="1" velocity="20"/>
    <joint_properties friction="0.0"/>
  </joint>
  <link name="spur_1m_24t_driven_4">
    <visual>
      <origin xyz="0 0 0" rpy="0 -0 0"/>
      <geometry>
        <mesh filename="../assemblies/right_arm_active/meshes/right_spur_1m_24t_driven_visual.stl"/>
      </geometry>
      <material name="spur_1m_24t_driven_material">
        <color rgba="0.23137254901960788156 0.38039215686274502337 0.7058823529411765163 1.0"/>
      </material>
    </visual>
    <inertial>
      <origin xyz="-2.690304390834019776e-18 -1.6883842059581361246e-15 -0.00097237500038395777158" rpy="0 0 0"/>
      <mass value="0.0026999999999999997093"/>
      <inertia ixx="1.2202334915684080498e-07" ixy="0" ixz="0" iyy="1.2202334915684064616e-07" iyz="-3.1611202962161956801e-37" izz="2.3180293204341252239e-07"/>
    </inertial>
  </link>
  <link name="sho_yaw_link_2">
    <visual>
      <origin xyz="0 0 0" rpy="0 -0 0"/>
      <geometry>
        <mesh filename="../assemblies/right_arm_active/meshes/right_sho_yaw_link_visual.stl"/>
      </geometry>
      <material name="sho_yaw_link_material">
        <color rgba="0.61568627450980395466 0.81176470588235294379 0.92941176470588238168 1.0"/>
      </material>
    </visual>
    <inertial>
      <origin xyz="-1.3035740535093626537e-18 2.6069328434162263936e-18 -0.024649285094360089132" rpy="0 0 0"/>
      <mass value="0.014500000000000007674"/>
      <inertia ixx="9.2365904614004439553e-06" ixy="3.5862833440690451918e-13" ixz="3.9137616104652588598e-44" iyy="5.8163826335078791714e-06" iyz="-5.7710285861749289932e-36" izz="4.5074356741562122031e-06"/>
    </inertial>
  </link>
  <link name="2xl430_gears_5">
    <visual>
      <origin xyz="0 0 0" rpy="0 -0 0"/>
      <geometry>
        <mesh filename="../assemblies/right_arm_active/meshes/right_2xl430_gears_2_visual.stl"/>
      </geometry>
      <material name="2xl430_gears_2_material">
        <color rgba="0.75914767920569214965 0.85560384745670925444 0.90519468321360607721 1.0"/>
      </material>
    </visual>
    <collision name="2xl430_gears_5_collision">
      <origin xyz="-0.011708886637741642 -0.002663752496014671 -0.019869324751325072" rpy="0 0 0"/>
      <geometry>
        <sphere radius="0.031174264351886416"/>
      </geometry>
    </collision>
    <inertial>
      <origin xyz="-0.011592905737984599349 -0.0024238553642520555345 -0.018551095523805894577" rpy="0 0 0"/>
      <mass value="0.11800003674524911501"/>
      <inertia ixx="2.7511021050426052092e-05" ixy="9.0043904315050616521e-07" ixz="-2.3349710123664931783e-08" iyy="3.2796197843347223622e-05" iyz="-6.5715119654724408728e-07" izz="3.5775739835742259337e-05"/>
    </inertial>
  </link>
  <link name="spur_1m_24t_drive_5">
    <visual>
      <origin xyz="0 0 0" rpy="0 -0 0"/>
      <geometry>
        <mesh filename="../assemblies/right_arm_active/meshes/right_spur_1m_24t_drive_2_visual.stl"/>
      </geometry>
      <material name="spur_1m_24t_drive_2_material">
        <color rgba="0.61568627450980395466 0.81176470588235294379 0.92941176470588238168 1.0"/>
      </material>
    </visual>
    <inertial>
      <origin xyz="3.0256643673369285924e-15 -3.3912620813973872492e-16 0.0048096451474092995898" rpy="0 0 0"/>
      <mass value="0.0031999999999999997197"/>
      <inertia ixx="1.4097598887016958673e-07" ixy="1.5562823048769074231e-15" ixz="-2.8340681600212421658e-36" iyy="1.4097598803635996198e-07" iyz="1.2526517803646001736e-36" izz="2.4107776386988835496e-07"/>
    </inertial>
  </link>
  <joint name="right_elbow_yaw_drive" type="fixed">
    <origin xyz="-0.024000000716147162905 -0.019000000152450874369 -0.019000000152450294971" rpy="1.5707963267950022512 -1.2151179192951298761e-14 -8.3478238015103697896e-15"/>
    <parent link="2xl430_gears_5"/>
    <child link="spur_1m_24t_drive_5"/>
    <axis xyz="0 0 1"/>
    <limit effort="1" velocity="20"/>
    <joint_properties friction="0.0"/>
  </joint>
  <link name="spur_1m_24t_driven_5">
    <visual>
      <origin xyz="0 0 0" rpy="0 -0 0"/>
      <geometry>
        <mesh filename="../assemblies/right_arm_active/meshes/right_spur_1m_24t_driven_2_visual.stl"/>
      </geometry>
      <material name="spur_1m_24t_driven_2_material">
        <color rgba="0.23137254901960788156 0.38039215686274502337 0.7058823529411765163 1.0"/>
      </material>
    </visual>
    <inertial>
      <origin xyz="-2.690304390834019776e-18 -1.6883842059581371106e-15 -0.00097237500038396460205" rpy="0 0 0"/>
      <mass value="0.0026999999999999997093"/>
      <inertia ixx="1.2202334915684080498e-07" ixy="3.8503779869585959908e-37" ixz="1.8410192092776977521e-66" iyy="1.2202334915684064616e-07" iyz="1.7901380328147422279e-36" izz="2.3180293204341252239e-07"/>
    </inertial>
  </link>
  <link name="elb_yaw_link_2">
    <visual>
      <origin xyz="0 0 0" rpy="0 -0 0"/>
      <geometry>
        <mesh filename="../assemblies/right_arm_active/meshes/right_elb_yaw_link_visual.stl"/>
      </geometry>
      <material name="elb_yaw_link_material">
        <color rgba="0.61568627450980395466 0.81176470588235294379 0.92941176470588227065 1.0"/>
      </material>
    </visual>
    <inertial>
      <origin xyz="5.3127688027774929136e-08 0.0019833638641961648559 -0.02341664355154993854" rpy="0 0 0"/>
      <mass value="0.017500000000000005135"/>
      <inertia ixx="1.4134344903109199776e-05" ixy="1.6945783922006116668e-12" ixz="-1.1286398721833140765e-11" iyy="6.6435900776211340404e-06" iyz="1.0545227077253051227e-06" izz="8.9925290757998993713e-06"/>
    </inertial>
  </link>
  <link name="spur_1m_24t_driven_6">
    <visual>
      <origin xyz="0 0 0" rpy="0 -0 0"/>
      <geometry>
        <mesh filename="../assemblies/right_arm_active/meshes/right_spur_1m_24t_driven_3_visual.stl"/>
      </geometry>
      <material name="spur_1m_24t_driven_3_material">
        <color rgba="0.23137254901960788156 0.38039215686274502337 0.7058823529411765163 1.0"/>
      </material>
    </visual>
    <inertial>
      <origin xyz="2.5065271224795038179e-17 -1.6883842059581323775e-15 -0.0025723750003839550293" rpy="0 0 0"/>
      <mass value="0.0026999999999999997093"/>
      <inertia ixx="1.2202334915684080498e-07" ixy="1.6801645595678856956e-36" ixz="1.4628821664372086897e-36" iyy="1.2202334915684064616e-07" iyz="0" izz="2.3180293204341252239e-07"/>
    </inertial>
  </link>
  <link name="2xl430_gears_6">
    <visual>
      <origin xyz="0 0 0" rpy="0 -0 0"/>
      <geometry>
        <mesh filename="../assemblies/right_arm_active/meshes/right_2xl430_gears_3_visual.stl"/>
      </geometry>
      <material name="2xl430_gears_3_material">
        <color rgba="0.75914767920569214965 0.85560384745670925444 0.90519468321360607721 1.0"/>
      </material>
    </visual>
    <collision name="2xl430_gears_6_collision">
      <origin xyz="-0.0008536254376340004 0.01171871446801601 -0.024337078544579577" rpy="0 0 0"/>
      <geometry>
        <sphere radius="0.031160574725534955"/>
      </geometry>
    </collision>
    <inertial>
      <origin xyz="0.00044890447620015019132 0.011592905379911784894 -0.024576144788197192698" rpy="0 0 0"/>
      <mass value="0.11800003674524911501"/>
      <inertia ixx="3.5775739835742767557e-05" ixy="2.3349710123598390066e-08" ixz="6.5715119654677461927e-07" iyy="2.7511021050425875909e-05" iyz="9.0043904315183537166e-07" izz="3.2796197843346695073e-05"/>
    </inertial>
  </link>
  <link name="spur_1m_24t_drive_6">
    <visual>
      <origin xyz="0 0 0" rpy="0 -0 0"/>
      <geometry>
        <mesh filename="../assemblies/right_arm_active/meshes/right_spur_1m_24t_drive_3_visual.stl"/>
      </geometry>
      <material name="spur_1m_24t_drive_3_material">
        <color rgba="0.61568627450980395466 0.81176470588235294379 0.92941176470588238168 1.0"/>
      </material>
    </visual>
    <inertial>
      <origin xyz="3.0326032612408362152e-15 -3.3912620813973872492e-16 0.0048096451474093065287" rpy="0 0 0"/>
      <mass value="0.0031999999999999997197"/>
      <inertia ixx="1.409759888701696132e-07" ixy="1.5562823122431795239e-15" ixz="9.6598469821100867444e-37" iyy="1.4097598803636004139e-07" iyz="-1.7762240303079187312e-37" izz="2.4107776386988835496e-07"/>
    </inertial>
  </link>
  <joint name="right_wrist_pitch_drive" type="fixed">
    <origin xyz="-1.5244312511681577095e-10 0.024000000358071732487 -0.0080000000000008709977" rpy="1.2483159056318864267e-14 7.3485321852726251993e-14 -1.5707963267948599206"/>
    <parent link="2xl430_gears_6"/>
    <child link="spur_1m_24t_drive_6"/>
    <axis xyz="0 0 1"/>
    <limit effort="1" velocity="20"/>
    <joint_properties friction="0.0"/>
  </joint>
  <link name="hand_2">
    <visual>
      <origin xyz="0 0 0" rpy="0 -0 0"/>
      <geometry>
        <mesh filename="../assemblies/right_arm_active/meshes/right_hand_visual.stl"/>
      </geometry>
      <material name="hand_material">
        <color rgba="0.64149913129808888712 0.67624720774385704836 0.69709605361131798951 1.0"/>
      </material>
    </visual>
    <collision name="hand_2_collision">
      <origin xyz="0.0044999998062849045 -0.023250000085681677 -0.019000000320374966" rpy="0 0 0"/>
      <geometry>
        <box size="0.05000000074505806 0.06749999988824129 0.07400000281631947"/>
      </geometry>
    </collision>
    <inertial>
      <origin xyz="0.0037132560777026323712 -0.042135580180293688568 -0.018486870577627653039" rpy="0 0 0"/>
      <mass value="0.039499999999999986511"/>
      <inertia ixx="2.4655505305535383863e-05" ixy="6.2292690365591973125e-07" ixz="-1.3905201231125081665e-08" iyy="2.5499495708696300544e-05" iyz="4.048228436147505174e-08" izz="1.3476712280060873444e-05"/>
    </inertial>
  </link>
  <joint name="right_wrist_roll" type="revolute">
    <origin xyz="0.019000000000002754269 -3.5806785314562716849e-10 -0.02700000015244990656" rpy="5.2111933288359401161e-30 1.570796326794831943 0"/>
    <parent link="2xl430_gears_6"/>
    <child link="hand_2"/>
    <axis xyz="0 0 1"/>
    <limit effort="1" velocity="20" lower="-1.3962634015954635824" upper="1.9198621771937625091"/>
    <joint_properties friction="0.0"/>
  </joint>
  <link name="wrist_bearing_plate_2">
    <visual>
      <origin xyz="0 0 0" rpy="0 -0 0"/>
      <geometry>
        <mesh filename="../assemblies/right_arm_active/meshes/right_wrist_bearing_plate_visual.stl"/>
      </geometry>
      <material name="wrist_bearing_plate_material">
        <color rgba="0.71932243125689054875 0.63128434304969727187 0.52422389360984933404 1.0"/>
      </material>
    </visual>
    <inertial>
      <origin xyz="-0.0075835583121499801351 -0.015499999999999977338 -0.0018386323705903331437" rpy="0 0 0"/>
      <mass value="0.0049000367468305557062"/>
      <inertia ixx="4.9707430109150129132e-07" ixy="1.3510663819638977183e-22" ixz="1.8100904820814035248e-08" iyy="7.1268523603538595411e-07" iyz="1.9159694223314982598e-23" izz="1.1919657811600109234e-06"/>
    </inertial>
  </link>
  <joint name="right_wrist_pitch_fixed" type="fixed">
    <origin xyz="0.015500000000003967202 4.5519144009631418157e-15 -0.045000000000003738398" rpy="-3.053113317715679127e-15 1.2051470932306202988e-13 -1.570796326794896558"/>
    <parent link="2xl430_gears_6"/>
    <child link="wrist_bearing_plate_2"/>
    <axis xyz="0 0 1"/>
    <limit effort="1" velocity="20"/>
    <joint_properties friction="0.0"/>
  </joint>
  <joint name="right_wrist_pitch" type="revolute">
    <origin xyz="2.7755575615628913511e-17 3.1554436208840472216e-30 -0.0015999999999999940051" rpy="-2.7183456742960519592e-16 6.3108872417680986472e-30 1.570796326794896558"/>
    <parent link="spur_1m_24t_driven_6"/>
    <child link="2xl430_gears_6"/>
    <axis xyz="0 0 1"/>
    <limit effort="1" velocity="20" lower="-1.9198621771937625091" upper="1.3962634015954635824"/>
    <joint_properties friction="0.0"/>
  </joint>
  <joint name="right_wrist_roll_fixed" type="fixed">
    <origin xyz="5.5220263365470826379e-30 -0.025299999999999999573 -0.051999999999999990674" rpy="1.570796326794896558 1.570796326794896558 0"/>
    <parent link="elb_yaw_link_2"/>
    <child link="spur_1m_24t_driven_6"/>
    <axis xyz="0 0 1"/>
    <limit effort="1" velocity="20"/>
    <joint_properties friction="0.0"/>
  </joint>
  <joint name="right_elbow_yaw_fixed" type="fixed">
    <origin xyz="-3.4694469519536141888e-18 7.8886090522101180541e-31 0.0015999999999999903189" rpy="3.141592653589793116 5.5511151240344814396e-17 -1.5707963267948970021"/>
    <parent link="spur_1m_24t_driven_5"/>
    <child link="elb_yaw_link_2"/>
    <axis xyz="0 0 1"/>
    <limit effort="1" velocity="20"/>
    <joint_properties friction="0.0"/>
  </joint>
  <joint name="right_elbow_yaw" type="revolute">
    <origin xyz="-3.5807255424624706563e-10 -0.027000000152453657032 -0.019000000000001768946" rpy="1.570796326794956066 3.0087043967523975425e-14 -4.0634162701317111644e-14"/>
    <parent link="2xl430_gears_5"/>
    <child link="spur_1m_24t_driven_5"/>
    <axis xyz="0 0 1"/>
    <limit effort="1" velocity="20" lower="-2.6179938779914944114" upper="2.6179938779914944114"/>
    <joint_properties friction="0.0"/>
  </joint>
  <joint name="right_elbow_roll" type="revolute">
    <origin xyz="-8.4654505627668186207e-16 -0.018999999999998996858 -0.05900000000000006628" rpy="1.570796326794896558 -7.4924624234411720275e-14 -2.6978419498846060156e-14"/>
    <parent link="sho_yaw_link_2"/>
    <child link="2xl430_gears_5"/>
    <axis xyz="0 0 1"/>
    <limit effort="1" velocity="20" lower="-1.9198621771937625091" upper="2.4434609527920612138"/>
    <joint_properties friction="0.0"/>
  </joint>
  <joint name="right_sho_yaw_fixed" type="fixed">
    <origin xyz="0 3.9443045261050590271e-31 0.0015999999999999972577" rpy="3.141592653589793116 -5.0487097934144755546e-29 -1.8301573001127473886e-28"/>
    <parent link="spur_1m_24t_driven_4"/>
    <child link="sho_yaw_link_2"/>
    <axis xyz="0 0 1"/>
    <limit effort="1" velocity="20"/>
    <joint_properties friction="0.0"/>
  </joint>
  <joint name="right_sho_yaw" type="revolute">
    <origin xyz="-3.5806816886529979627e-10 -0.027000000152446666096 -0.019000000000003354483" rpy="1.5707963267949260899 -2.2055090607973039157e-14 7.6050277186033683693e-15"/>
    <parent link="2xl430_gears_4"/>
    <child link="spur_1m_24t_driven_4"/>
    <axis xyz="0 0 1"/>
    <limit effort="1" velocity="20" lower="-2.6179938779914944114" upper="2.6179938779914944114"/>
    <joint_properties friction="0.0"/>
  </joint>
  <joint name="right_sho_roll" type="revolute">
    <origin xyz="-0.018999999999999999528 9.3241386833306442318e-18 0.027000000000000006634" rpy="3.141592653589793116 1.5707963267948952257 0"/>
    <parent link="sho_pitch_link_2"/>
    <child link="2xl430_gears_4"/>
    <axis xyz="0 0 1"/>
    <limit effort="1" velocity="20" lower="-1.570796326794896558" upper="0.34906585039886589561"/>
    <joint_properties friction="0.0"/>
  </joint>
</robot>