<?xml version="1.0" ?><robot name="sysID_2XL430">  
  <link name="2xl430">    
    <visual>      
      <origin xyz="0 0 0" rpy="0 -0 0"/>      
      <geometry>        
        <mesh filename="package:///meshes/2xl430_visual.stl"/>        
      </geometry>      
      <material name="2xl430_material">        
        <color rgba="0.7477423961173667033 0.84014146741504380778 0.89001491737990712227 1.0"/>        
      </material>      
    </visual>    
    <collision>      
      <origin xyz="0 0 0" rpy="0 -0 0"/>      
      <geometry>        
        <mesh filename="package:///meshes/2xl430_collision.stl"/>        
      </geometry>      
    </collision>    
    <inertial>      
      <origin xyz="0.074637808447704373505 0.017802872414827662639 0.0060007862055428563136" rpy="0 0 0"/>      
      <mass value="0.127849999998418562"/>      
      <inertia ixx="4.488893921080776739e-05" ixy="-5.9504395818475946692e-06" ixz="-6.9374906701103073016e-07" iyy="4.3761239815176705985e-05" iyz="-1.7042449579308646464e-07" izz="5.7422593236642115535e-05"/>      
    </inertial>    
  </link>  

  <link name="arm_430">    
    <visual>      
      <origin xyz="0 0 0" rpy="0 -0 0"/>      
      <geometry>        
        <mesh filename="package:///meshes/arm_430_visual.stl"/>        
      </geometry>      
      <material name="arm_430_material">        
        <color rgba="0.63059283987567615881 0.65298952457695413898 0.67418901807298259321 1.0"/>        
      </material>      
    </visual>    
    <collision>      
      <origin xyz="0 0 0" rpy="0 -0 0"/>      
      <geometry>        
        <mesh filename="package:///meshes/arm_430_collision.stl"/>        
      </geometry>      
    </collision>    
    <inertial>      
      <origin xyz="-0.077790387031995575362 1.3637865612826564917e-05 -0.018999999999999888506" rpy="0 0 0"/>      
      <mass value="0.25549999999999989386"/>      
      <inertia ixx="0.00024426144376378419428" ixy="-9.4015858833451833388e-08" ixz="5.1301965805423025813e-20" iyy="0.00041073874164066626188" iyz="1.4859916801881504815e-16" izz="0.00022084196523238376186"/>      
    </inertial>    
  </link>  

  <joint name="joint_0" type="revolute">    
    <origin xyz="0.057999999999999982125 0.032699858285928966317 0.0056193957935184602609" rpy="1.570796326794896558 -2.2412627309618028409e-15 -1.5707963267949029973"/>    
    <parent link="2xl430"/>    
    <child link="arm_430"/>    
    <axis xyz="0 0 1"/>    
    <limit effort="1" velocity="20" lower="-1.570796326794896558" upper="1.570796326794896558"/>    
    <joint_properties friction="0.0"/>    
  </joint>  


</robot>