<?xml version="1.0" ?><robot name="sysID_XM430">  
  <link name="xm430">    
    <visual>      
      <origin xyz="0 0 0" rpy="0 -0 0"/>      
      <geometry>        
        <mesh filename="package:///meshes/xm430_visual.stl"/>        
      </geometry>      
      <material name="xm430_material">        
        <color rgba="0.91426034379578902112 0.70000842084638215113 0.1302479088754292802 1.0"/>        
      </material>      
    </visual>    
    <collision>      
      <origin xyz="0 0 0" rpy="0 -0 0"/>      
      <geometry>        
        <mesh filename="package:///meshes/xm430_collision.stl"/>        
      </geometry>      
    </collision>    
    <inertial>      
      <origin xyz="0.07195813595556013742 0.017445641259993493327 0.0055435138757473417445" rpy="0 0 0"/>      
      <mass value="0.1034500000044496909"/>      
      <inertia ixx="3.2324316568160280452e-05" ixy="-6.1940121394904689206e-06" ixz="-3.1148674256865578655e-08" iyy="3.2377737272392996743e-05" iyz="-4.6596185424276485742e-08" izz="4.8950379202494915772e-05"/>      
    </inertial>    
  </link>  

  <link name="arm_430">    
    <visual>      
      <origin xyz="0 0 0" rpy="0 -0 0"/>      
      <geometry>        
        <mesh filename="package:///meshes/arm_430_visual.stl"/>        
      </geometry>      
      <material name="arm_430_material">        
        <color rgba="0.63059283987567615881 0.65298952457695413898 0.67418901807298259321 1.0"/>        
      </material>      
    </visual>    
    <collision>      
      <origin xyz="0 0 0" rpy="0 -0 0"/>      
      <geometry>        
        <mesh filename="package:///meshes/arm_430_collision.stl"/>        
      </geometry>      
    </collision>    
    <inertial>      
      <origin xyz="-0.077790387031997226819 -1.3637865612588745171e-05 -0.019000000000000284023" rpy="0 0 0"/>      
      <mass value="0.25549999999999989386"/>      
      <inertia ixx="0.00024426144376379796365" ixy="9.4015858830096471186e-08" ixz="-1.3501724960961450956e-18" iyy="0.00041073874164068962644" iyz="1.4686505773996030592e-16" izz="0.00022084196523238964365"/>      
    </inertial>    
  </link>  

  <joint name="joint_0" type="revolute">    
    <origin xyz="0.093000000000000013212 0.032699857927858892725 0.0055693959459662215755" rpy="-1.570796326794896558 2.7547408798512016148e-15 -1.5707963267948912289"/>    
    <parent link="xm430"/>    
    <child link="arm_430"/>    
    <axis xyz="0 0 1"/>    
    <limit effort="1" velocity="20" lower="-1.570796326794896558" upper="1.570796326794896558"/>    
    <joint_properties friction="0.0"/>    
  </joint>  


</robot>