<?xml version="1.0" ?><robot name="left_arm_active">  
  <link name="sho_pitch_link">    
    <visual>      
      <origin xyz="0 0 0" rpy="0 -0 0"/>      
      <geometry>        
        <mesh filename="package:///meshes/left_sho_pitch_link_visual.stl"/>        
      </geometry>      
      <material name="sho_pitch_link_material">        
        <color rgba="0.61568627450980395466 0.81176470588235294379 0.92941176470588227065 1.0"/>        
      </material>      
    </visual>    
    <collision>      
      <origin xyz="0 0 0" rpy="0 -0 0"/>      
      <geometry>        
        <mesh filename="package:///meshes/left_sho_pitch_link_collision.stl"/>        
      </geometry>      
    </collision>    
    <inertial>      
      <origin xyz="-1.025903438159899119e-18 -2.1966078074444220184e-18 0.012913250798677602602" rpy="0 0 0"/>      
      <mass value="0.0085999999999999982708"/>      
      <inertia ixx="1.8365636406635814379e-06" ixy="0" ixz="0" iyy="4.0110869076839152165e-06" iyz="0" izz="3.5160516450492493809e-06"/>      
    </inertial>    
  </link>  

  <link name="2xl430_gears">    
    <visual>      
      <origin xyz="0 0 0" rpy="0 -0 0"/>      
      <geometry>        
        <mesh filename="package:///meshes/left_2xl430_gears_visual.stl"/>        
      </geometry>      
      <material name="2xl430_gears_material">        
        <color rgba="0.75914767920569214965 0.85560384745670925444 0.90519468321360607721 1.0"/>        
      </material>      
    </visual>    
    <collision>      
      <origin xyz="0 0 0" rpy="0 -0 0"/>      
      <geometry>        
        <mesh filename="package:///meshes/left_2xl430_gears_collision.stl"/>        
      </geometry>      
    </collision>    
    <inertial>      
      <origin xyz="-0.011592905737981719708 -0.0024238553642539654651 -0.018551095523800652243" rpy="0 0 0"/>      
      <mass value="0.11800003674524911501"/>      
      <inertia ixx="2.7511021050425137297e-05" ixy="9.0043904315059743301e-07" ixz="-2.3349710123436745739e-08" iyy="3.2796197843345773501e-05" iyz="-6.5715119654595532665e-07" izz="3.577573983574187309e-05"/>      
    </inertial>    
  </link>  

  <link name="spur_1m_24t_drive">    
    <visual>      
      <origin xyz="0 0 0" rpy="0 -0 0"/>      
      <geometry>        
        <mesh filename="package:///meshes/left_spur_1m_24t_drive_visual.stl"/>        
      </geometry>      
      <material name="spur_1m_24t_drive_material">        
        <color rgba="0.61568627450980395466 0.81176470588235294379 0.92941176470588238168 1.0"/>        
      </material>      
    </visual>    
    <collision>      
      <origin xyz="0 0 0" rpy="0 -0 0"/>      
      <geometry>        
        <mesh filename="package:///meshes/left_spur_1m_24t_drive_collision.stl"/>        
      </geometry>      
    </collision>    
    <inertial>      
      <origin xyz="3.0326032611483892113e-15 -3.3912620811388928147e-16 0.0048096451474093108655" rpy="0 0 0"/>      
      <mass value="0.0031999999999999997197"/>      
      <inertia ixx="1.409759888701696132e-07" ixy="1.5562823114660456276e-15" ixz="-2.008449854153761406e-29" iyy="1.4097598803635996198e-07" iyz="1.6394294515261297612e-30" izz="2.4107776386988835496e-07"/>      
    </inertial>    
  </link>  

  <joint name="left_sho_yaw_drive" type="fixed">    
    <origin xyz="-0.024000000716141011575 -0.019000000152450600283 -0.019000000152443286688" rpy="1.5707963267948328312 -1.2315316060159674745e-15 7.63621479414374471e-14"/>    
    <parent link="2xl430_gears"/>    
    <child link="spur_1m_24t_drive"/>    
    <axis xyz="0 0 1"/>    
    <limit effort="1" velocity="20"/>    
    <joint_properties friction="0.0"/>    
  </joint>  

  <link name="spur_1m_24t_driven">    
    <visual>      
      <origin xyz="0 0 0" rpy="0 -0 0"/>      
      <geometry>        
        <mesh filename="package:///meshes/left_spur_1m_24t_driven_visual.stl"/>        
      </geometry>      
      <material name="spur_1m_24t_driven_material">        
        <color rgba="0.23137254901960788156 0.38039215686274502337 0.7058823529411765163 1.0"/>        
      </material>      
    </visual>    
    <collision>      
      <origin xyz="0 0 0" rpy="0 -0 0"/>      
      <geometry>        
        <mesh filename="package:///meshes/left_spur_1m_24t_driven_collision.stl"/>        
      </geometry>      
    </collision>    
    <inertial>      
      <origin xyz="-6.1597507571280238057e-18 -1.688384205958136519e-15 -0.00097237500038395777158" rpy="0 0 0"/>      
      <mass value="0.0026999999999999997093"/>      
      <inertia ixx="1.2202334915684085792e-07" ixy="2.7523294133209990513e-36" ixz="-7.3269571490458995975e-30" iyy="1.2202334915684064616e-07" iyz="2.3906142240509615961e-38" izz="2.3180293204341252239e-07"/>      
    </inertial>    
  </link>  

  <link name="sho_yaw_link">    
    <visual>      
      <origin xyz="0 0 0" rpy="0 -0 0"/>      
      <geometry>        
        <mesh filename="package:///meshes/left_sho_yaw_link_visual.stl"/>        
      </geometry>      
      <material name="sho_yaw_link_material">        
        <color rgba="0.61568627450980395466 0.81176470588235294379 0.92941176470588238168 1.0"/>        
      </material>      
    </visual>    
    <collision>      
      <origin xyz="0 0 0" rpy="0 -0 0"/>      
      <geometry>        
        <mesh filename="package:///meshes/left_sho_yaw_link_collision.stl"/>        
      </geometry>      
    </collision>    
    <inertial>      
      <origin xyz="-1.3035750898319770195e-18 2.6069328434161451193e-18 -0.024649285094360082193" rpy="0 0 0"/>      
      <mass value="0.014500000000000007674"/>      
      <inertia ixx="9.2365904614004473434e-06" ixy="3.5862833440690462015e-13" ixz="9.1428418910883641815e-28" iyy="5.8163826335078791714e-06" iyz="3.2690928711022967479e-35" izz="4.5074356741562122031e-06"/>      
    </inertial>    
  </link>  

  <link name="2xl430_gears_2">    
    <visual>      
      <origin xyz="0 0 0" rpy="0 -0 0"/>      
      <geometry>        
        <mesh filename="package:///meshes/left_2xl430_gears_2_visual.stl"/>        
      </geometry>      
      <material name="2xl430_gears_2_material">        
        <color rgba="0.75914767920569214965 0.85560384745670925444 0.90519468321360607721 1.0"/>        
      </material>      
    </visual>    
    <collision>      
      <origin xyz="0 0 0" rpy="0 -0 0"/>      
      <geometry>        
        <mesh filename="package:///meshes/left_2xl430_gears_2_collision.stl"/>        
      </geometry>      
    </collision>    
    <inertial>      
      <origin xyz="-0.011592905737977830458 -0.0024238553642531319304 -0.018551095523810002402" rpy="0 0 0"/>      
      <mass value="0.11800003674524911501"/>      
      <inertia ixx="2.7511021050425449005e-05" ixy="9.0043904315422929852e-07" ixz="-2.3349710124855247993e-08" iyy="3.2796197843347501448e-05" iyz="-6.5715119654968301277e-07" izz="3.577573983574221868e-05"/>      
    </inertial>    
  </link>  

  <link name="spur_1m_24t_drive_2">    
    <visual>      
      <origin xyz="0 0 0" rpy="0 -0 0"/>      
      <geometry>        
        <mesh filename="package:///meshes/left_spur_1m_24t_drive_2_visual.stl"/>        
      </geometry>      
      <material name="spur_1m_24t_drive_2_material">        
        <color rgba="0.61568627450980395466 0.81176470588235294379 0.92941176470588238168 1.0"/>        
      </material>      
    </visual>    
    <collision>      
      <origin xyz="0 0 0" rpy="0 -0 0"/>      
      <geometry>        
        <mesh filename="package:///meshes/left_spur_1m_24t_drive_2_collision.stl"/>        
      </geometry>      
    </collision>    
    <inertial>      
      <origin xyz="3.0326032635612721456e-15 -3.3912620813973872492e-16 0.0048096451474093134676" rpy="0 0 0"/>      
      <mass value="0.0031999999999999997197"/>      
      <inertia ixx="1.4097598887016953379e-07" ixy="1.5562823114943523235e-15" ixz="-4.6297932308656121067e-28" iyy="1.4097598803635996198e-07" iyz="2.2330386657934582872e-29" izz="2.4107776386988835496e-07"/>      
    </inertial>    
  </link>  

  <joint name="left_elbow_yaw_drive" type="fixed">    
    <origin xyz="-0.024000000716137552537 -0.019000000152447502066 -0.019000000152459547986" rpy="1.5707963267950562081 -2.470655165606289817e-13 -1.8325179468455831644e-13"/>    
    <parent link="2xl430_gears_2"/>    
    <child link="spur_1m_24t_drive_2"/>    
    <axis xyz="0 0 1"/>    
    <limit effort="1" velocity="20"/>    
    <joint_properties friction="0.0"/>    
  </joint>  

  <link name="spur_1m_24t_driven_2">    
    <visual>      
      <origin xyz="0 0 0" rpy="0 -0 0"/>      
      <geometry>        
        <mesh filename="package:///meshes/left_spur_1m_24t_driven_2_visual.stl"/>        
      </geometry>      
      <material name="spur_1m_24t_driven_2_material">        
        <color rgba="0.23137254901960788156 0.38039215686274502337 0.7058823529411765163 1.0"/>        
      </material>      
    </visual>    
    <collision>      
      <origin xyz="0 0 0" rpy="0 -0 0"/>      
      <geometry>        
        <mesh filename="package:///meshes/left_spur_1m_24t_driven_2_collision.stl"/>        
      </geometry>      
    </collision>    
    <inertial>      
      <origin xyz="-2.6919984763826045554e-18 -1.6851535667301797593e-15 -0.00097237500038395083268" rpy="0 0 0"/>      
      <mass value="0.0026999999999999997093"/>      
      <inertia ixx="1.2202334915684080498e-07" ixy="-1.4158378337979601932e-26" ixz="-1.6652141981526740106e-31" iyy="1.2202334915684064616e-07" iyz="-6.1216890803012590929e-29" izz="2.3180293204341252239e-07"/>      
    </inertial>    
  </link>  

  <link name="elb_yaw_link">    
    <visual>      
      <origin xyz="0 0 0" rpy="0 -0 0"/>      
      <geometry>        
        <mesh filename="package:///meshes/left_elb_yaw_link_visual.stl"/>        
      </geometry>      
      <material name="elb_yaw_link_material">        
        <color rgba="0.61568627450980395466 0.81176470588235294379 0.92941176470588227065 1.0"/>        
      </material>      
    </visual>    
    <collision>      
      <origin xyz="0 0 0" rpy="0 -0 0"/>      
      <geometry>        
        <mesh filename="package:///meshes/left_elb_yaw_link_collision.stl"/>        
      </geometry>      
    </collision>    
    <inertial>      
      <origin xyz="5.3127688027775035015e-08 0.0019833638641961613865 -0.023416643551549952418" rpy="0 0 0"/>      
      <mass value="0.017500000000000005135"/>      
      <inertia ixx="1.4134344903109199776e-05" ixy="1.6945783922010719072e-12" ixz="-1.1286398721833085835e-11" iyy="6.6435900776211340404e-06" iyz="1.0545227077253051227e-06" izz="8.9925290757998993713e-06"/>      
    </inertial>    
  </link>  

  <link name="spur_1m_24t_driven_3">    
    <visual>      
      <origin xyz="0 0 0" rpy="0 -0 0"/>      
      <geometry>        
        <mesh filename="package:///meshes/left_spur_1m_24t_driven_3_visual.stl"/>        
      </geometry>      
      <material name="spur_1m_24t_driven_3_material">        
        <color rgba="0.23137254901960788156 0.38039215686274502337 0.7058823529411765163 1.0"/>        
      </material>      
    </visual>    
    <collision>      
      <origin xyz="0 0 0" rpy="0 -0 0"/>      
      <geometry>        
        <mesh filename="package:///meshes/left_spur_1m_24t_driven_3_collision.stl"/>        
      </geometry>      
    </collision>    
    <inertial>      
      <origin xyz="-2.6903273536523174272e-18 -1.6883828105019308173e-15 -0.0025723750003839550293" rpy="0 0 0"/>      
      <mass value="0.0026999999999999997093"/>      
      <inertia ixx="1.2202334915684080498e-07" ixy="-6.8849887603967411276e-32" ixz="-2.6410010759070278003e-28" iyy="1.2202334915684059322e-07" iyz="2.0286938869726816775e-26" izz="2.3180293204341252239e-07"/>      
    </inertial>    
  </link>  

  <link name="2xl430_gears_3">    
    <visual>      
      <origin xyz="0 0 0" rpy="0 -0 0"/>      
      <geometry>        
        <mesh filename="package:///meshes/left_2xl430_gears_3_visual.stl"/>        
      </geometry>      
      <material name="2xl430_gears_3_material">        
        <color rgba="0.75914767920569214965 0.85560384745670925444 0.90519468321360607721 1.0"/>        
      </material>      
    </visual>    
    <collision>      
      <origin xyz="0 0 0" rpy="0 -0 0"/>      
      <geometry>        
        <mesh filename="package:///meshes/left_2xl430_gears_3_collision.stl"/>        
      </geometry>      
    </collision>    
    <inertial>      
      <origin xyz="0.00044890447620203518522 0.011592905379898215887 -0.024576144788197726992" rpy="0 0 0"/>      
      <mass value="0.11800003674524911501"/>      
      <inertia ixx="3.5775739835741527501e-05" ixy="2.3349710123577267181e-08" ixz="6.571511965489162362e-07" iyy="2.7511021050426404458e-05" iyz="9.0043904315389906155e-07" izz="3.2796197843345726067e-05"/>      
    </inertial>    
  </link>  

  <link name="spur_1m_24t_drive_3">    
    <visual>      
      <origin xyz="0 0 0" rpy="0 -0 0"/>      
      <geometry>        
        <mesh filename="package:///meshes/left_spur_1m_24t_drive_3_visual.stl"/>        
      </geometry>      
      <material name="spur_1m_24t_drive_3_material">        
        <color rgba="0.61568627450980395466 0.81176470588235294379 0.92941176470588238168 1.0"/>        
      </material>      
    </visual>    
    <collision>      
      <origin xyz="0 0 0" rpy="0 -0 0"/>      
      <geometry>        
        <mesh filename="package:///meshes/left_spur_1m_24t_drive_3_collision.stl"/>        
      </geometry>      
    </collision>    
    <inertial>      
      <origin xyz="3.060358827889013058e-15 -3.4111303900242703925e-16 0.0048096451474093065287" rpy="0 0 0"/>      
      <mass value="0.0031999999999999997197"/>      
      <inertia ixx="1.4097598887016953379e-07" ixy="1.5562823135089737022e-15" ixz="-1.1512514101231046835e-27" iyy="1.4097598803635998845e-07" iyz="2.2291261639049831572e-27" izz="2.4107776386988835496e-07"/>      
    </inertial>    
  </link>  

  <joint name="left_wrist_pitch_drive" type="fixed">    
    <origin xyz="-1.524411534503666843e-10 0.024000000358058687366 -0.0080000000000068870187" rpy="9.3688325669630329923e-15 -2.4754144734777612982e-13 -1.570796326794971387"/>    
    <parent link="2xl430_gears_3"/>    
    <child link="spur_1m_24t_drive_3"/>    
    <axis xyz="0 0 1"/>    
    <limit effort="1" velocity="20"/>    
    <joint_properties friction="0.0"/>    
  </joint>  

  <link name="hand">    
    <visual>      
      <origin xyz="0 0 0" rpy="0 -0 0"/>      
      <geometry>        
        <mesh filename="package:///meshes/left_hand_visual.stl"/>        
      </geometry>      
      <material name="hand_material">        
        <color rgba="0.6414991312980887761 0.67624720774385704836 0.69709605361131787848 1.0"/>        
      </material>      
    </visual>    
    <collision>      
      <origin xyz="0 0 0" rpy="0 -0 0"/>      
      <geometry>        
        <mesh filename="package:///meshes/left_hand_collision.stl"/>        
      </geometry>      
    </collision>    
    <inertial>      
      <origin xyz="-0.0037132560743682236672 0.042135580180293723263 -0.019513129422372363364" rpy="0 0 0"/>      
      <mass value="0.039500000000000000389"/>      
      <inertia ixx="2.4655505305536037772e-05" ixy="6.2292690516536515991e-07" ixz="-1.3905202790257463006e-08" iyy="2.5499495709674586328e-05" iyz="4.0482284361505544926e-08" izz="1.3476712281039084689e-05"/>      
    </inertial>    
  </link>  

  <joint name="left_wrist_roll" type="revolute">    
    <origin xyz="0.019000000000007864764 -3.580815921555569048e-10 -0.027000000152448074692" rpy="-3.141592653589793116 -1.5707963267945825869 0"/>    
    <parent link="2xl430_gears_3"/>    
    <child link="hand"/>    
    <axis xyz="0 0 1"/>    
    <limit effort="1" velocity="20" lower="-1.9198621771937625091" upper="1.3962634015954635824"/>    
    <joint_properties friction="0.0"/>    
  </joint>  

  <link name="wrist_bearing_plate">    
    <visual>      
      <origin xyz="0 0 0" rpy="0 -0 0"/>      
      <geometry>        
        <mesh filename="package:///meshes/left_wrist_bearing_plate_visual.stl"/>        
      </geometry>      
      <material name="wrist_bearing_plate_material">        
        <color rgba="0.71932243125689054875 0.63128434304969727187 0.52422389360984933404 1.0"/>        
      </material>      
    </visual>    
    <collision>      
      <origin xyz="0 0 0" rpy="0 -0 0"/>      
      <geometry>        
        <mesh filename="package:///meshes/left_wrist_bearing_plate_collision.stl"/>        
      </geometry>      
    </collision>    
    <inertial>      
      <origin xyz="-0.007583558312149987074 -0.015499999999999972133 -0.0018386323705903283732" rpy="0 0 0"/>      
      <mass value="0.0049000367468305557062"/>      
      <inertia ixx="4.9707430109150107956e-07" ixy="5.8442651625198521782e-23" ixz="1.8100904820814022013e-08" iyy="7.1268523603538521295e-07" iyz="1.0938305468180491225e-23" izz="1.1919657811600107117e-06"/>      
    </inertial>    
  </link>  

  <joint name="left_wrist_pitch_fixed" type="fixed">    
    <origin xyz="0.015500000000007483486 -1.7374990335383699858e-14 -0.044999999999998908928" rpy="4.0578672398099256913e-14 -2.8213543071750907979e-13 -1.570796326794906328"/>    
    <parent link="2xl430_gears_3"/>    
    <child link="wrist_bearing_plate"/>    
    <axis xyz="0 0 1"/>    
    <limit effort="1" velocity="20"/>    
    <joint_properties friction="0.0"/>    
  </joint>  

  <joint name="left_wrist_pitch" type="revolute">    
    <origin xyz="0 -1.3383120566617945357e-18 -0.0015999999999999961735" rpy="-2.8942931320395828399e-14 -2.5018666387969439484e-14 -1.5029360097675703578"/>    
    <parent link="spur_1m_24t_driven_3"/>    
    <child link="2xl430_gears_3"/>    
    <axis xyz="0 0 1"/>    
    <limit effort="1" velocity="20" lower="-1.3962634015954635824" upper="1.9198621771937625091"/>    
    <joint_properties friction="0.0"/>    
  </joint>  

  <joint name="left_wrist_roll_fixed" type="fixed">    
    <origin xyz="-1.6940658945086006781e-21 -0.025299999999999999573 -0.052000000000000032307" rpy="1.5707963267949238695 -1.5707963267948696906 0"/>    
    <parent link="elb_yaw_link"/>    
    <child link="spur_1m_24t_driven_3"/>    
    <axis xyz="0 0 1"/>    
    <limit effort="1" velocity="20"/>    
    <joint_properties friction="0.0"/>    
  </joint>  

  <joint name="left_elbow_yaw_fixed" type="fixed">    
    <origin xyz="0 3.4694469519536141888e-18 0.0015999999999999903189" rpy="3.141592653589793116 1.7371588856516367895e-15 -7.1482908950121119081e-21"/>    
    <parent link="spur_1m_24t_driven_2"/>    
    <child link="elb_yaw_link"/>    
    <axis xyz="0 0 1"/>    
    <limit effort="1" velocity="20"/>    
    <joint_properties friction="0.0"/>    
  </joint>  

  <joint name="left_elbow_yaw" type="revolute">    
    <origin xyz="-3.5806394654835926872e-10 -0.027000000152452907631 -0.019000000000006612294" rpy="-1.5707963271033555941 1.5702961013580483129 3.1415926532772431301"/>    
    <parent link="2xl430_gears_2"/>    
    <child link="spur_1m_24t_driven_2"/>    
    <axis xyz="0 0 1"/>    
    <limit effort="1" velocity="20" lower="-2.6179938779914944114" upper="2.6179938779914944114"/>    
    <joint_properties friction="0.0"/>    
  </joint>  

  <joint name="left_elbow_roll" type="revolute">    
    <origin xyz="0 -0.019000000000000002998 -0.05900000000000000383" rpy="1.570796326794896558 -9.1511985033140475399e-06 9.9917328930995459489e-16"/>    
    <parent link="sho_yaw_link"/>    
    <child link="2xl430_gears_2"/>    
    <axis xyz="0 0 1"/>    
    <limit effort="1" velocity="20" lower="-1.9198621771937625091" upper="2.4434609527920612138"/>    
    <joint_properties friction="0.0"/>    
  </joint>  

  <joint name="left_sho_yaw_fixed" type="fixed">    
    <origin xyz="-6.9388939039072283776e-18 0 0.0015999999999999972577" rpy="-3.1415926535897917837 7.771562309448331808e-16 7.7715611725339221982e-16"/>    
    <parent link="spur_1m_24t_driven"/>    
    <child link="sho_yaw_link"/>    
    <axis xyz="0 0 1"/>    
    <limit effort="1" velocity="20"/>    
    <joint_properties friction="0.0"/>    
  </joint>  

  <joint name="left_sho_yaw" type="revolute">    
    <origin xyz="-3.5807029216683439188e-10 -0.027000000152450923108 -0.018999999999999881567" rpy="1.5707963267948492625 7.0146039834906763197e-14 9.489446512533569504e-14"/>    
    <parent link="2xl430_gears"/>    
    <child link="spur_1m_24t_driven"/>    
    <axis xyz="0 0 1"/>    
    <limit effort="1" velocity="20" lower="-2.6179938779914944114" upper="2.6179938779914944114"/>    
    <joint_properties friction="0.0"/>    
  </joint>  

  <joint name="left_sho_roll" type="revolute">    
    <origin xyz="-0.018999999999999999528 1.0056362270253492431e-17 0.027000000000000003164" rpy="3.141592653589793116 1.5707956970996790336 0"/>    
    <parent link="sho_pitch_link"/>    
    <child link="2xl430_gears"/>    
    <axis xyz="0 0 1"/>    
    <limit effort="1" velocity="20" lower="-1.570796326794896558" upper="0.34906585039886589561"/>    
    <joint_properties friction="0.0"/>    
  </joint>  


</robot>