<?xml version="1.0" ?><robot name="sysID_XC430">  
  <link name="xc430">    
    <visual>      
      <origin xyz="0 0 0" rpy="0 -0 0"/>      
      <geometry>        
        <mesh filename="package:///meshes/xc430_visual.stl"/>        
      </geometry>      
      <material name="xc430_material">        
        <color rgba="0.44786462886842598463 0.53733448957467955243 0.69800988116095863401 1.0"/>        
      </material>      
    </visual>    
    <collision>      
      <origin xyz="0 0 0" rpy="0 -0 0"/>      
      <geometry>        
        <mesh filename="package:///meshes/xc430_collision.stl"/>        
      </geometry>      
    </collision>    
    <inertial>      
      <origin xyz="0.070922443962646866678 0.016712412139443775377 0.0055430119111927371803" rpy="0 0 0"/>      
      <mass value="0.086449999993020193445"/>      
      <inertia ixx="2.783593789528892261e-05" ixy="-5.7442278246997916427e-06" ixz="-3.9581376465552392383e-08" iyy="2.9061697096170713126e-05" iyz="-5.0973493978132244245e-08" izz="4.3242134177796969418e-05"/>      
    </inertial>    
  </link>  

  <link name="arm_430">    
    <visual>      
      <origin xyz="0 0 0" rpy="0 -0 0"/>      
      <geometry>        
        <mesh filename="package:///meshes/arm_430_visual.stl"/>        
      </geometry>      
      <material name="arm_430_material">        
        <color rgba="0.63059283987567615881 0.65298952457695413898 0.67418901807298259321 1.0"/>        
      </material>      
    </visual>    
    <collision>      
      <origin xyz="0 0 0" rpy="0 -0 0"/>      
      <geometry>        
        <mesh filename="package:///meshes/arm_430_collision.stl"/>        
      </geometry>      
    </collision>    
    <inertial>      
      <origin xyz="-0.077790387031996297007 1.3637865612734507683e-05 -0.018999999999999978711" rpy="0 0 0"/>      
      <mass value="0.25549999999999989386"/>      
      <inertia ixx="0.00024426144376378918161" ixy="-9.4015858831613083678e-08" ixz="5.2512936060477332147e-20" iyy="0.00041073874164067580286" iyz="1.4659069535758831107e-16" izz="0.00022084196523238815288"/>      
    </inertial>    
  </link>  

  <joint name="joint_0" type="revolute">    
    <origin xyz="0.054999999999999681088 0.032699857927858962114 0.0055693959459660142761" rpy="1.57079632679489678 -5.5511151231258061214e-17 -1.5707963267948972241"/>    
    <parent link="xc430"/>    
    <child link="arm_430"/>    
    <axis xyz="0 0 1"/>    
    <limit effort="1" velocity="20" lower="-1.570796326794896558" upper="1.570796326794896558"/>    
    <joint_properties friction="0.0"/>    
  </joint>  


</robot>