<?xml version="1.0" ?>
<mujoco model="sysID_XC330">
  <compiler angle="radian" autolimits="true"/>
  <asset>
    <mesh name="xc330_visual" file="../assemblies/sysID_XC330/meshes/xc330_visual.stl"/>
    <mesh name="arm_330_visual" file="../assemblies/sysID_XC330/meshes/arm_330_visual.stl"/>
  </asset>
  <worldbody>
    <geom type="mesh" rgba="0.662917 0.7055 0.667299 1" mesh="xc330_visual" class="visual"/>
    <body name="arm_330" pos="0.0894 0.0219499 0.0034194" quat="0.5 0.5 0.5 0.5">
      <inertial pos="0.0777716 1.36379e-05 -0.0145" quat="0.707306 0 0 0.706908" mass="0.2555" diaginertia="0.000410316 0.000243223 0.000221442"/>
      <joint name="joint_0" pos="0 0 0" axis="0 0 1" range="-1.5708 1.5708" damping="0.134" armature="0.0035" frictionloss="0.014"/>
      <geom type="mesh" rgba="0.630593 0.65299 0.674189 1" mesh="arm_330_visual" class="visual"/>
    </body>
  </worldbody>
  <option>
    <flag eulerdamp="disable"/>
  </option>
  <equality/>
  <contact/>
  <actuator>
    <motor name="joint_0" joint="joint_0" class="XC330"/>
  </actuator>
  <default>
    <default class="visual">
      <geom type="mesh" contype="0" conaffinity="0" group="2"/>
    </default>
    <default class="collision">
      <geom group="3"/>
    </default>
    <default class="XC330">
      <motor ctrlrange="-1 1"/>
    </default>
  </default>
</mujoco>